Workbook
Name Potatoes: Dates!$O$11:$O$15
Name Spring_Grain: Dates!$P$11:$P$15
Name Wheat: Dates!$R$11:$R$15
Name Winter_Grain: Dates!$Q$11:$Q$15

Sheet Group 1
A1: =E4 -> Brent | L1: `
A2: Field | B2: YTD | C2: Farm | D2: Group | E2: Manager | F2: Crop | G2: Variety | H2: =Dates!F2 -> 45453 | I2: =Dates!G2 -> 45460 | J2: =Dates!H2 -> 45467 | K2: =Dates!I2 -> 45474 | L2: =Dates!J2 -> 45481 | M2: =Dates!K2 -> 45488 | N2: =Dates!L2 -> 45495 | O2: =Dates!M2 -> 45502 | ... AB2: =Dates!Z2 -> 45593
A3: Rain | B3: =+SUM(H3:AB3) -> 0.23 | H3: ='Rain Totals'!H2 -> 0 | I3: ='Rain Totals'!I2 -> 0.03 | J3: ='Rain Totals'!J2 -> 0 | K3: ='Rain Totals'!K2 -> 0 | L3: ='Rain Totals'!L2 -> 0.2 | M3: ='Rain Totals'!M2 -> 0 | N3: ='Rain Totals'!N2 -> 0 | O3: ='Rain Totals'!O2 -> 0 | ... AB3: ='Rain Totals'!AB2 -> 0
A4: =Data!A2 -> .ET 1 | B4: =IFERROR(VLOOKUP($A4,Data!$1:$1048576,34,FALSE),) -> 21.75 | C4: =IFERROR(VLOOKUP($A4,Data!$1:$1048576,2,FALSE),) -> Imperial | D4: =IFERROR(VLOOKUP($A4,Data!$1:$1048576,3,FALSE),) -> 1 | E4: =IFERROR(VLOOKUP($A4,Data!$1:$1048576,4,FALSE),) -> Brent | F4: =IFERROR(VLOOKUP($A4,Data!$1:$1048576,6,FALSE),) -> Spring Grain | G4: =IFERROR(VLOOKUP($A4,Data!$1:$1048576,7,FALSE),) -> Cannon Rent | H4: =IFERROR(VLOOKUP($A4,Data!$1:$1048576,13,FALSE),) -> 2.24 | I4: =IFERROR(VLOOKUP($A4,Data!$1:$1048576,14,FALSE),) -> 2.03 | J4: =IFERROR(VLOOKUP($A4,Data!$1:$1048576,15,FALSE),) -> 1.99 | K4: =IFERROR(VLOOKUP($A4,Data!$1:$1048576,16,FALSE),) -> 1.94 | L4: =IFERROR(VLOOKUP($A4,Data!$1:$1048576,17,FALSE),) -> 1.68 | M4: =IFERROR(VLOOKUP($A4,Data!$1:$1048576,18,FALSE),) -> 1.69 | N4: =IFERROR(VLOOKUP($A4,Data!$1:$1048576,19,FALSE),) -> 1.77 | O4: =IFERROR(VLOOKUP($A4,Data!$1:$1048576,20,FALSE),) -> 1.82 | P4: =IFERROR(VLOOKUP($A4,Data!$1:$1048576,21,FALSE),) -> 1.61 | Q4: =IFERROR(VLOOKUP($A4,Data!$1:$1048576,22,FALSE),) -> 1.22 | R4: =IFERROR(VLOOKUP($A4,Data!$1:$1048576,23,FALSE),) -> 0.13 | S4: =IFERROR(VLOOKUP($A4,Data!$1:$1048576,24,FALSE),) -> 0 | T4: =IFERROR(VLOOKUP($A4,Data!$1:$1048576,25,FALSE),) -> 0 | U4: =IFERROR(VLOOKUP($A4,Data!$1:$1048576,26,FALSE),) -> 0 | V4: =IFERROR(VLOOKUP($A4,Data!$1:$1048576,27,FALSE),) -> 0 | W4: =IFERROR(VLOOKUP($A4,Data!$1:$1048576,28,FALSE),) -> 0 | X4: =IFERROR(VLOOKUP($A4,Data!$1:$1048576,29,FALSE),) -> 0 | Y4: =IFERROR(VLOOKUP($A4,Data!$1:$1048576,30,FALSE),) -> 0 | Z4: =IFERROR(VLOOKUP($A4,Data!$1:$1048576,31,FALSE),) -> 0 | AA4: =IFERROR(VLOOKUP($A4,Data!$1:$1048576,32,FALSE),) -> 0 | AB4: =IFERROR(VLOOKUP($A4,Data!$1:$1048576,33,FALSE),) -> 0
A5: =Data!A3 -> I-4 | B5: =IFERROR(VLOOKUP($A5,Data!$1:$1048576,34,FALSE),) -> 19.33 | C5: =IFERROR(VLOOKUP($A5,Data!$1:$1048576,2,FALSE),) -> Imperial | D5: =IFERROR(VLOOKUP($A5,Data!$1:$1048576,3,FALSE),) -> 1 | E5: =IFERROR(VLOOKUP($A5,Data!$1:$1048576,4,FALSE),) -> Brent | F5: =IFERROR(VLOOKUP($A5,Data!$1:$1048576,6,FALSE),) -> Spring Grain | G5: =IFERROR(VLOOKUP($A5,Data!$1:$1048576,7,FALSE),) -> Cannon Rent | H5: =IFERROR(VLOOKUP($A5,Data!$1:$1048576,13,FALSE),) | I5: =IFERROR(VLOOKUP($A5,Data!$1:$1048576,14,FALSE),) -> 2.33 | J5: =IFERROR(VLOOKUP($A5,Data!$1:$1048576,15,FALSE),) -> 2.19 | K5: =IFERROR(VLOOKUP($A5,Data!$1:$1048576,16,FALSE),) -> 4.95 | L5: =IFERROR(VLOOKUP($A5,Data!$1:$1048576,17,FALSE),) -> 2.19 | M5: =IFERROR(VLOOKUP($A5,Data!$1:$1048576,18,FALSE),) -> 2.26 | N5: =IFERROR(VLOOKUP($A5,Data!$1:$1048576,19,FALSE),) -> 2.46 | O5: =IFERROR(VLOOKUP($A5,Data!$1:$1048576,20,FALSE),) -> 0.17 | P5: =IFERROR(VLOOKUP($A5,Data!$1:$1048576,21,FALSE),) -> 0 | Q5: =IFERROR(VLOOKUP($A5,Data!$1:$1048576,22,FALSE),) -> 0 | R5: =IFERROR(VLOOKUP($A5,Data!$1:$1048576,23,FALSE),) -> 0 | S5: =IFERROR(VLOOKUP($A5,Data!$1:$1048576,24,FALSE),) -> 0 | T5: =IFERROR(VLOOKUP($A5,Data!$1:$1048576,25,FALSE),) -> 0 | U5: =IFERROR(VLOOKUP($A5,Data!$1:$1048576,26,FALSE),) -> 0 | V5: =IFERROR(VLOOKUP($A5,Data!$1:$1048576,27,FALSE),) -> 0.55 | W5: =IFERROR(VLOOKUP($A5,Data!$1:$1048576,28,FALSE),) -> 0.93 | X5: =IFERROR(VLOOKUP($A5,Data!$1:$1048576,29,FALSE),) -> 0 | Y5: =IFERROR(VLOOKUP($A5,Data!$1:$1048576,30,FALSE),) -> 0 | Z5: =IFERROR(VLOOKUP($A5,Data!$1:$1048576,31,FALSE),) -> 0 | AA5: =IFERROR(VLOOKUP($A5,Data!$1:$1048576,32,FALSE),) -> 0 | AB5: =IFERROR(VLOOKUP($A5,Data!$1:$1048576,33,FALSE),) -> 0
A6: =Data!A4 -> I-14 | B6: =IFERROR(VLOOKUP($A6,Data!$1:$1048576,34,FALSE),) -> 22.27 | C6: =IFERROR(VLOOKUP($A6,Data!$1:$1048576,2,FALSE),) -> Imperial | D6: =IFERROR(VLOOKUP($A6,Data!$1:$1048576,3,FALSE),) -> 1 | E6: =IFERROR(VLOOKUP($A6,Data!$1:$1048576,4,FALSE),) -> Brent | F6: =IFERROR(VLOOKUP($A6,Data!$1:$1048576,6,FALSE),) -> Spring Grain | G6: =IFERROR(VLOOKUP($A6,Data!$1:$1048576,7,FALSE),) -> Cannon Rent | H6: =IFERROR(VLOOKUP($A6,Data!$1:$1048576,13,FALSE),) | I6: =IFERROR(VLOOKUP($A6,Data!$1:$1048576,14,FALSE),) -> 2.42 | J6: =IFERROR(VLOOKUP($A6,Data!$1:$1048576,15,FALSE),) -> 2.45 | K6: =IFERROR(VLOOKUP($A6,Data!$1:$1048576,16,FALSE),) -> 5.12 | L6: =IFERROR(VLOOKUP($A6,Data!$1:$1048576,17,FALSE),) -> 2.1 | M6: =IFERROR(VLOOKUP($A6,Data!$1:$1048576,18,FALSE),) -> 2.07 | N6: =IFERROR(VLOOKUP($A6,Data!$1:$1048576,19,FALSE),) -> 2.36 | O6: =IFERROR(VLOOKUP($A6,Data!$1:$1048576,20,FALSE),) -> 0.09 | P6: =IFERROR(VLOOKUP($A6,Data!$1:$1048576,21,FALSE),) -> 0 | Q6: =IFERROR(VLOOKUP($A6,Data!$1:$1048576,22,FALSE),) -> 0 | R6: =IFERROR(VLOOKUP($A6,Data!$1:$1048576,23,FALSE),) -> 0 | S6: =IFERROR(VLOOKUP($A6,Data!$1:$1048576,24,FALSE),) -> 0 | T6: =IFERROR(VLOOKUP($A6,Data!$1:$1048576,25,FALSE),) -> 0 | U6: =IFERROR(VLOOKUP($A6,Data!$1:$1048576,26,FALSE),) -> 0 | V6: =IFERROR(VLOOKUP($A6,Data!$1:$1048576,27,FALSE),) -> 0 | W6: =IFERROR(VLOOKUP($A6,Data!$1:$1048576,28,FALSE),) -> 0.73 | X6: =IFERROR(VLOOKUP($A6,Data!$1:$1048576,29,FALSE),) -> 1.14 | Y6: =IFERROR(VLOOKUP($A6,Data!$1:$1048576,30,FALSE),) -> 0 | Z6: =IFERROR(VLOOKUP($A6,Data!$1:$1048576,31,FALSE),) -> 0 | AA6: =IFERROR(VLOOKUP($A6,Data!$1:$1048576,32,FALSE),) -> 0 | AB6: =IFERROR(VLOOKUP($A6,Data!$1:$1048576,33,FALSE),) -> 0
A7: =Data!A5 -> I-15 | B7: =IFERROR(VLOOKUP($A7,Data!$1:$1048576,34,FALSE),) -> 20.53 | C7: =IFERROR(VLOOKUP($A7,Data!$1:$1048576,2,FALSE),) -> Imperial | D7: =IFERROR(VLOOKUP($A7,Data!$1:$1048576,3,FALSE),) -> 1 | E7: =IFERROR(VLOOKUP($A7,Data!$1:$1048576,4,FALSE),) -> Brent | F7: =IFERROR(VLOOKUP($A7,Data!$1:$1048576,6,FALSE),) -> Spring Grain | G7: =IFERROR(VLOOKUP($A7,Data!$1:$1048576,7,FALSE),) -> Cannon Rent | H7: =IFERROR(VLOOKUP($A7,Data!$1:$1048576,13,FALSE),) | I7: =IFERROR(VLOOKUP($A7,Data!$1:$1048576,14,FALSE),) -> 2.53 | J7: =IFERROR(VLOOKUP($A7,Data!$1:$1048576,15,FALSE),) -> 2.42 | K7: =IFERROR(VLOOKUP($A7,Data!$1:$1048576,16,FALSE),) -> 5.13 | L7: =IFERROR(VLOOKUP($A7,Data!$1:$1048576,17,FALSE),) -> 2.38 | M7: =IFERROR(VLOOKUP($A7,Data!$1:$1048576,18,FALSE),) -> 2.32 | N7: =IFERROR(VLOOKUP($A7,Data!$1:$1048576,19,FALSE),) -> 2.53 | O7: =IFERROR(VLOOKUP($A7,Data!$1:$1048576,20,FALSE),) -> 0.14 | P7: =IFERROR(VLOOKUP($A7,Data!$1:$1048576,21,FALSE),) -> 0 | Q7: =IFERROR(VLOOKUP($A7,Data!$1:$1048576,22,FALSE),) -> 0 | R7: =IFERROR(VLOOKUP($A7,Data!$1:$1048576,23,FALSE),) -> 0 | S7: =IFERROR(VLOOKUP($A7,Data!$1:$1048576,24,FALSE),) -> 0 | T7: =IFERROR(VLOOKUP($A7,Data!$1:$1048576,25,FALSE),) -> 0 | U7: =IFERROR(VLOOKUP($A7,Data!$1:$1048576,26,FALSE),) -> 0 | V7: =IFERROR(VLOOKUP($A7,Data!$1:$1048576,27,FALSE),) -> 0 | W7: =IFERROR(VLOOKUP($A7,Data!$1:$1048576,28,FALSE),) -> 0.74 | X7: =IFERROR(VLOOKUP($A7,Data!$1:$1048576,29,FALSE),) -> 1.13 | Y7: =IFERROR(VLOOKUP($A7,Data!$1:$1048576,30,FALSE),) -> 0 | Z7: =IFERROR(VLOOKUP($A7,Data!$1:$1048576,31,FALSE),) -> 0 | AA7: =IFERROR(VLOOKUP($A7,Data!$1:$1048576,32,FALSE),) -> 0 | AB7: =IFERROR(VLOOKUP($A7,Data!$1:$1048576,33,FALSE),) -> 0
A8: =Data!A6 -> I-20 | B8: =IFERROR(VLOOKUP($A8,Data!$1:$1048576,34,FALSE),) -> 19.51 | C8: =IFERROR(VLOOKUP($A8,Data!$1:$1048576,2,FALSE),) -> Imperial | D8: =IFERROR(VLOOKUP($A8,Data!$1:$1048576,3,FALSE),) -> 1 | E8: =IFERROR(VLOOKUP($A8,Data!$1:$1048576,4,FALSE),) -> Brent | F8: =IFERROR(VLOOKUP($A8,Data!$1:$1048576,6,FALSE),) -> Spring Grain | G8: =IFERROR(VLOOKUP($A8,Data!$1:$1048576,7,FALSE),) -> Cannon Rent | H8: =IFERROR(VLOOKUP($A8,Data!$1:$1048576,13,FALSE),) | I8: =IFERROR(VLOOKUP($A8,Data!$1:$1048576,14,FALSE),) -> 2.32 | J8: =IFERROR(VLOOKUP($A8,Data!$1:$1048576,15,FALSE),) -> 2.24 | K8: =IFERROR(VLOOKUP($A8,Data!$1:$1048576,16,FALSE),) -> 5.04 | L8: =IFERROR(VLOOKUP($A8,Data!$1:$1048576,17,FALSE),) -> 2.27 | M8: =IFERROR(VLOOKUP($A8,Data!$1:$1048576,18,FALSE),) -> 2.07 | N8: =IFERROR(VLOOKUP($A8,Data!$1:$1048576,19,FALSE),) -> 2.31 | O8: =IFERROR(VLOOKUP($A8,Data!$1:$1048576,20,FALSE),) -> 0 | P8: =IFERROR(VLOOKUP($A8,Data!$1:$1048576,21,FALSE),) -> 0 | Q8: =IFERROR(VLOOKUP($A8,Data!$1:$1048576,22,FALSE),) -> 0 | R8: =IFERROR(VLOOKUP($A8,Data!$1:$1048576,23,FALSE),) -> 0 | S8: =IFERROR(VLOOKUP($A8,Data!$1:$1048576,24,FALSE),) -> 0 | T8: =IFERROR(VLOOKUP($A8,Data!$1:$1048576,25,FALSE),) -> 0 | U8: =IFERROR(VLOOKUP($A8,Data!$1:$1048576,26,FALSE),) -> 0 | V8: =IFERROR(VLOOKUP($A8,Data!$1:$1048576,27,FALSE),) -> 0 | W8: =IFERROR(VLOOKUP($A8,Data!$1:$1048576,28,FALSE),) -> 0.92 | X8: =IFERROR(VLOOKUP($A8,Data!$1:$1048576,29,FALSE),) -> 0.95 | Y8: =IFERROR(VLOOKUP($A8,Data!$1:$1048576,30,FALSE),) -> 0 | Z8: =IFERROR(VLOOKUP($A8,Data!$1:$1048576,31,FALSE),) -> 0 | AA8: =IFERROR(VLOOKUP($A8,Data!$1:$1048576,32,FALSE),) -> 0 | AB8: =IFERROR(VLOOKUP($A8,Data!$1:$1048576,33,FALSE),) -> 0
A9: =Data!A7 -> I-21 | B9: =IFERROR(VLOOKUP($A9,Data!$1:$1048576,34,FALSE),) -> 20.61 | C9: =IFERROR(VLOOKUP($A9,Data!$1:$1048576,2,FALSE),) -> Imperial | D9: =IFERROR(VLOOKUP($A9,Data!$1:$1048576,3,FALSE),) -> 1 | E9: =IFERROR(VLOOKUP($A9,Data!$1:$1048576,4,FALSE),) -> Brent | F9: =IFERROR(VLOOKUP($A9,Data!$1:$1048576,6,FALSE),) -> Spring Grain | G9: =IFERROR(VLOOKUP($A9,Data!$1:$1048576,7,FALSE),) -> Cannon Rent | H9: =IFERROR(VLOOKUP($A9,Data!$1:$1048576,13,FALSE),) | I9: =IFERROR(VLOOKUP($A9,Data!$1:$1048576,14,FALSE),) -> 2.55 | J9: =IFERROR(VLOOKUP($A9,Data!$1:$1048576,15,FALSE),) -> 2.33 | K9: =IFERROR(VLOOKUP($A9,Data!$1:$1048576,16,FALSE),) -> 5.1 | L9: =IFERROR(VLOOKUP($A9,Data!$1:$1048576,17,FALSE),) -> 2.55 | M9: =IFERROR(VLOOKUP($A9,Data!$1:$1048576,18,FALSE),) -> 2.3 | N9: =IFERROR(VLOOKUP($A9,Data!$1:$1048576,19,FALSE),) -> 2.13 | O9: =IFERROR(VLOOKUP($A9,Data!$1:$1048576,20,FALSE),) -> 0.15 | P9: =IFERROR(VLOOKUP($A9,Data!$1:$1048576,21,FALSE),) -> 0 | Q9: =IFERROR(VLOOKUP($A9,Data!$1:$1048576,22,FALSE),) -> 0 | R9: =IFERROR(VLOOKUP($A9,Data!$1:$1048576,23,FALSE),) -> 0 | S9: =IFERROR(VLOOKUP($A9,Data!$1:$1048576,24,FALSE),) -> 0 | T9: =IFERROR(VLOOKUP($A9,Data!$1:$1048576,25,FALSE),) -> 0 | U9: =IFERROR(VLOOKUP($A9,Data!$1:$1048576,26,FALSE),) -> 0.19 | V9: =IFERROR(VLOOKUP($A9,Data!$1:$1048576,27,FALSE),) -> 0.01 | W9: =IFERROR(VLOOKUP($A9,Data!$1:$1048576,28,FALSE),) -> 0.9 | X9: =IFERROR(VLOOKUP($A9,Data!$1:$1048576,29,FALSE),) -> 1.14 | Y9: =IFERROR(VLOOKUP($A9,Data!$1:$1048576,30,FALSE),) -> 0 | Z9: =IFERROR(VLOOKUP($A9,Data!$1:$1048576,31,FALSE),) -> 0 | AA9: =IFERROR(VLOOKUP($A9,Data!$1:$1048576,32,FALSE),) -> 0 | AB9: =IFERROR(VLOOKUP($A9,Data!$1:$1048576,33,FALSE),) -> 0
A10: =Data!A8 -> 0 | B10: =IFERROR(VLOOKUP($A10,Data!$1:$1048576,34,FALSE),) -> 0 | C10: =IFERROR(VLOOKUP($A10,Data!$1:$1048576,2,FALSE),) -> 0 | D10: =IFERROR(VLOOKUP($A10,Data!$1:$1048576,3,FALSE),) -> 0 | E10: =IFERROR(VLOOKUP($A10,Data!$1:$1048576,4,FALSE),) -> 0 | F10: =IFERROR(VLOOKUP($A10,Data!$1:$1048576,6,FALSE),) -> 0 | G10: =IFERROR(VLOOKUP($A10,Data!$1:$1048576,7,FALSE),) -> 0 | H10: =IFERROR(VLOOKUP($A10,Data!$1:$1048576,13,FALSE),) -> 0 | I10: =IFERROR(VLOOKUP($A10,Data!$1:$1048576,14,FALSE),) -> 0 | J10: =IFERROR(VLOOKUP($A10,Data!$1:$1048576,15,FALSE),) -> 0 | K10: =IFERROR(VLOOKUP($A10,Data!$1:$1048576,16,FALSE),) -> 0 | L10: =IFERROR(VLOOKUP($A10,Data!$1:$1048576,17,FALSE),) -> 0 | M10: =IFERROR(VLOOKUP($A10,Data!$1:$1048576,18,FALSE),) -> 0 | N10: =IFERROR(VLOOKUP($A10,Data!$1:$1048576,19,FALSE),) -> 0 | O10: =IFERROR(VLOOKUP($A10,Data!$1:$1048576,20,FALSE),) -> 0 | P10: =IFERROR(VLOOKUP($A10,Data!$1:$1048576,21,FALSE),) -> 0 | Q10: =IFERROR(VLOOKUP($A10,Data!$1:$1048576,22,FALSE),) -> 0 | R10: =IFERROR(VLOOKUP($A10,Data!$1:$1048576,23,FALSE),) -> 0 | S10: =IFERROR(VLOOKUP($A10,Data!$1:$1048576,24,FALSE),) -> 0 | T10: =IFERROR(VLOOKUP($A10,Data!$1:$1048576,25,FALSE),) -> 0 | U10: =IFERROR(VLOOKUP($A10,Data!$1:$1048576,26,FALSE),) -> 0 | V10: =IFERROR(VLOOKUP($A10,Data!$1:$1048576,27,FALSE),) -> 0 | W10: =IFERROR(VLOOKUP($A10,Data!$1:$1048576,28,FALSE),) -> 0 | X10: =IFERROR(VLOOKUP($A10,Data!$1:$1048576,29,FALSE),) -> 0 | Y10: =IFERROR(VLOOKUP($A10,Data!$1:$1048576,30,FALSE),) -> 0 | Z10: =IFERROR(VLOOKUP($A10,Data!$1:$1048576,31,FALSE),) -> 0 | AA10: =IFERROR(VLOOKUP($A10,Data!$1:$1048576,32,FALSE),) -> 0 | AB10: =IFERROR(VLOOKUP($A10,Data!$1:$1048576,33,FALSE),) -> 0
A11: =Data!A9 -> 0 | B11: =IFERROR(VLOOKUP($A11,Data!$1:$1048576,34,FALSE),) -> 0 | C11: =IFERROR(VLOOKUP($A11,Data!$1:$1048576,2,FALSE),) -> 0 | D11: =IFERROR(VLOOKUP($A11,Data!$1:$1048576,3,FALSE),) -> 0 | E11: =IFERROR(VLOOKUP($A11,Data!$1:$1048576,4,FALSE),) -> 0 | F11: =IFERROR(VLOOKUP($A11,Data!$1:$1048576,6,FALSE),) -> 0 | G11: =IFERROR(VLOOKUP($A11,Data!$1:$1048576,7,FALSE),) -> 0 | H11: =IFERROR(VLOOKUP($A11,Data!$1:$1048576,13,FALSE),) -> 0 | I11: =IFERROR(VLOOKUP($A11,Data!$1:$1048576,14,FALSE),) -> 0 | J11: =IFERROR(VLOOKUP($A11,Data!$1:$1048576,15,FALSE),) -> 0 | K11: =IFERROR(VLOOKUP($A11,Data!$1:$1048576,16,FALSE),) -> 0 | L11: =IFERROR(VLOOKUP($A11,Data!$1:$1048576,17,FALSE),) -> 0 | M11: =IFERROR(VLOOKUP($A11,Data!$1:$1048576,18,FALSE),) -> 0 | N11: =IFERROR(VLOOKUP($A11,Data!$1:$1048576,19,FALSE),) -> 0 | O11: =IFERROR(VLOOKUP($A11,Data!$1:$1048576,20,FALSE),) -> 0 | P11: =IFERROR(VLOOKUP($A11,Data!$1:$1048576,21,FALSE),) -> 0 | Q11: =IFERROR(VLOOKUP($A11,Data!$1:$1048576,22,FALSE),) -> 0 | R11: =IFERROR(VLOOKUP($A11,Data!$1:$1048576,23,FALSE),) -> 0 | S11: =IFERROR(VLOOKUP($A11,Data!$1:$1048576,24,FALSE),) -> 0 | T11: =IFERROR(VLOOKUP($A11,Data!$1:$1048576,25,FALSE),) -> 0 | U11: =IFERROR(VLOOKUP($A11,Data!$1:$1048576,26,FALSE),) -> 0 | V11: =IFERROR(VLOOKUP($A11,Data!$1:$1048576,27,FALSE),) -> 0 | W11: =IFERROR(VLOOKUP($A11,Data!$1:$1048576,28,FALSE),) -> 0 | X11: =IFERROR(VLOOKUP($A11,Data!$1:$1048576,29,FALSE),) -> 0 | Y11: =IFERROR(VLOOKUP($A11,Data!$1:$1048576,30,FALSE),) -> 0 | Z11: =IFERROR(VLOOKUP($A11,Data!$1:$1048576,31,FALSE),) -> 0 | AA11: =IFERROR(VLOOKUP($A11,Data!$1:$1048576,32,FALSE),) -> 0 | AB11: =IFERROR(VLOOKUP($A11,Data!$1:$1048576,33,FALSE),) -> 0
A12: =Data!A10 -> 0 | B12: =IFERROR(VLOOKUP($A12,Data!$1:$1048576,34,FALSE),) -> 0 | C12: =IFERROR(VLOOKUP($A12,Data!$1:$1048576,2,FALSE),) -> 0 | D12: =IFERROR(VLOOKUP($A12,Data!$1:$1048576,3,FALSE),) -> 0 | E12: =IFERROR(VLOOKUP($A12,Data!$1:$1048576,4,FALSE),) -> 0 | F12: =IFERROR(VLOOKUP($A12,Data!$1:$1048576,6,FALSE),) -> 0 | G12: =IFERROR(VLOOKUP($A12,Data!$1:$1048576,7,FALSE),) -> 0 | H12: =IFERROR(VLOOKUP($A12,Data!$1:$1048576,13,FALSE),) -> 0 | I12: =IFERROR(VLOOKUP($A12,Data!$1:$1048576,14,FALSE),) -> 0 | J12: =IFERROR(VLOOKUP($A12,Data!$1:$1048576,15,FALSE),) -> 0 | K12: =IFERROR(VLOOKUP($A12,Data!$1:$1048576,16,FALSE),) -> 0 | L12: =IFERROR(VLOOKUP($A12,Data!$1:$1048576,17,FALSE),) -> 0 | M12: =IFERROR(VLOOKUP($A12,Data!$1:$1048576,18,FALSE),) -> 0 | N12: =IFERROR(VLOOKUP($A12,Data!$1:$1048576,19,FALSE),) -> 0 | O12: =IFERROR(VLOOKUP($A12,Data!$1:$1048576,20,FALSE),) -> 0 | P12: =IFERROR(VLOOKUP($A12,Data!$1:$1048576,21,FALSE),) -> 0 | Q12: =IFERROR(VLOOKUP($A12,Data!$1:$1048576,22,FALSE),) -> 0 | R12: =IFERROR(VLOOKUP($A12,Data!$1:$1048576,23,FALSE),) -> 0 | S12: =IFERROR(VLOOKUP($A12,Data!$1:$1048576,24,FALSE),) -> 0 | T12: =IFERROR(VLOOKUP($A12,Data!$1:$1048576,25,FALSE),) -> 0 | U12: =IFERROR(VLOOKUP($A12,Data!$1:$1048576,26,FALSE),) -> 0 | V12: =IFERROR(VLOOKUP($A12,Data!$1:$1048576,27,FALSE),) -> 0 | W12: =IFERROR(VLOOKUP($A12,Data!$1:$1048576,28,FALSE),) -> 0 | X12: =IFERROR(VLOOKUP($A12,Data!$1:$1048576,29,FALSE),) -> 0 | Y12: =IFERROR(VLOOKUP($A12,Data!$1:$1048576,30,FALSE),) -> 0 | Z12: =IFERROR(VLOOKUP($A12,Data!$1:$1048576,31,FALSE),) -> 0 | AA12: =IFERROR(VLOOKUP($A12,Data!$1:$1048576,32,FALSE),) -> 0 | AB12: =IFERROR(VLOOKUP($A12,Data!$1:$1048576,33,FALSE),) -> 0
A13: =Data!A11 -> 0 | B13: =IFERROR(VLOOKUP($A13,Data!$1:$1048576,34,FALSE),) -> 0 | C13: =IFERROR(VLOOKUP($A13,Data!$1:$1048576,2,FALSE),) -> 0 | D13: =IFERROR(VLOOKUP($A13,Data!$1:$1048576,3,FALSE),) -> 0 | E13: =IFERROR(VLOOKUP($A13,Data!$1:$1048576,4,FALSE),) -> 0 | F13: =IFERROR(VLOOKUP($A13,Data!$1:$1048576,6,FALSE),) -> 0 | G13: =IFERROR(VLOOKUP($A13,Data!$1:$1048576,7,FALSE),) -> 0 | H13: =IFERROR(VLOOKUP($A13,Data!$1:$1048576,13,FALSE),) -> 0 | I13: =IFERROR(VLOOKUP($A13,Data!$1:$1048576,14,FALSE),) -> 0 | J13: =IFERROR(VLOOKUP($A13,Data!$1:$1048576,15,FALSE),) -> 0 | K13: =IFERROR(VLOOKUP($A13,Data!$1:$1048576,16,FALSE),) -> 0 | L13: =IFERROR(VLOOKUP($A13,Data!$1:$1048576,17,FALSE),) -> 0 | M13: =IFERROR(VLOOKUP($A13,Data!$1:$1048576,18,FALSE),) -> 0 | N13: =IFERROR(VLOOKUP($A13,Data!$1:$1048576,19,FALSE),) -> 0 | O13: =IFERROR(VLOOKUP($A13,Data!$1:$1048576,20,FALSE),) -> 0 | P13: =IFERROR(VLOOKUP($A13,Data!$1:$1048576,21,FALSE),) -> 0 | Q13: =IFERROR(VLOOKUP($A13,Data!$1:$1048576,22,FALSE),) -> 0 | R13: =IFERROR(VLOOKUP($A13,Data!$1:$1048576,23,FALSE),) -> 0 | S13: =IFERROR(VLOOKUP($A13,Data!$1:$1048576,24,FALSE),) -> 0 | T13: =IFERROR(VLOOKUP($A13,Data!$1:$1048576,25,FALSE),) -> 0 | U13: =IFERROR(VLOOKUP($A13,Data!$1:$1048576,26,FALSE),) -> 0 | V13: =IFERROR(VLOOKUP($A13,Data!$1:$1048576,27,FALSE),) -> 0 | W13: =IFERROR(VLOOKUP($A13,Data!$1:$1048576,28,FALSE),) -> 0 | X13: =IFERROR(VLOOKUP($A13,Data!$1:$1048576,29,FALSE),) -> 0 | Y13: =IFERROR(VLOOKUP($A13,Data!$1:$1048576,30,FALSE),) -> 0 | Z13: =IFERROR(VLOOKUP($A13,Data!$1:$1048576,31,FALSE),) -> 0 | AA13: =IFERROR(VLOOKUP($A13,Data!$1:$1048576,32,FALSE),) -> 0 | AB13: =IFERROR(VLOOKUP($A13,Data!$1:$1048576,33,FALSE),) -> 0

Sheet Group 2
A1: =E4 -> Brent
A2: Field | B2: YTD | C2: Farm | D2: Group | E2: Manager | F2: Crop | G2: Variety | H2: =Dates!F2 -> 45453 | I2: =Dates!G2 -> 45460 | J2: =Dates!H2 -> 45467 | K2: =Dates!I2 -> 45474 | L2: =Dates!J2 -> 45481 | M2: =Dates!K2 -> 45488 | N2: =Dates!L2 -> 45495 | O2: =Dates!M2 -> 45502 | ... AB2: =Dates!Z2 -> 45593
A3: Rain | B3: =+SUM(H3:AB3) -> 0.23 | H3: ='Rain Totals'!H2 -> 0 | I3: ='Rain Totals'!I2 -> 0.03 | J3: ='Rain Totals'!J2 -> 0 | K3: ='Rain Totals'!K2 -> 0 | L3: ='Rain Totals'!L2 -> 0.2 | M3: ='Rain Totals'!M2 -> 0 | N3: ='Rain Totals'!N2 -> 0 | O3: ='Rain Totals'!O2 -> 0 | ... AB3: ='Rain Totals'!AB2 -> 0
A4: =Data!A12 -> .ET 2 | B4: =IFERROR(VLOOKUP($A4,Data!$1:$1048576,34,FALSE),) -> 21.75 | C4: =IFERROR(VLOOKUP($A4,Data!$1:$1048576,2,FALSE),) -> Imperial | D4: =IFERROR(VLOOKUP($A4,Data!$1:$1048576,3,FALSE),) -> 2 | E4: =IFERROR(VLOOKUP($A4,Data!$1:$1048576,4,FALSE),) -> Brent | F4: =IFERROR(VLOOKUP($A4,Data!$1:$1048576,6,FALSE),) -> Spring Grain | G4: =IFERROR(VLOOKUP($A4,Data!$1:$1048576,7,FALSE),) -> Lott Rent | H4: =IFERROR(VLOOKUP($A4,Data!$1:$1048576,13,FALSE),) -> 2.24 | I4: =IFERROR(VLOOKUP($A4,Data!$1:$1048576,14,FALSE),) -> 2.03 | J4: =IFERROR(VLOOKUP($A4,Data!$1:$1048576,15,FALSE),) -> 1.99 | K4: =IFERROR(VLOOKUP($A4,Data!$1:$1048576,16,FALSE),) -> 1.94 | L4: =IFERROR(VLOOKUP($A4,Data!$1:$1048576,17,FALSE),) -> 1.68 | M4: =IFERROR(VLOOKUP($A4,Data!$1:$1048576,18,FALSE),) -> 1.69 | N4: =IFERROR(VLOOKUP($A4,Data!$1:$1048576,19,FALSE),) -> 1.77 | O4: =IFERROR(VLOOKUP($A4,Data!$1:$1048576,20,FALSE),) -> 1.82 | P4: =IFERROR(VLOOKUP($A4,Data!$1:$1048576,21,FALSE),) -> 1.61 | Q4: =IFERROR(VLOOKUP($A4,Data!$1:$1048576,22,FALSE),) -> 1.22 | R4: =IFERROR(VLOOKUP($A4,Data!$1:$1048576,23,FALSE),) -> 0.13 | S4: =IFERROR(VLOOKUP($A4,Data!$1:$1048576,24,FALSE),) -> 0 | T4: =IFERROR(VLOOKUP($A4,Data!$1:$1048576,25,FALSE),) -> 0 | U4: =IFERROR(VLOOKUP($A4,Data!$1:$1048576,26,FALSE),) -> 0 | V4: =IFERROR(VLOOKUP($A4,Data!$1:$1048576,27,FALSE),) -> 0 | W4: =IFERROR(VLOOKUP($A4,Data!$1:$1048576,28,FALSE),) -> 0 | X4: =IFERROR(VLOOKUP($A4,Data!$1:$1048576,29,FALSE),) -> 0 | Y4: =IFERROR(VLOOKUP($A4,Data!$1:$1048576,30,FALSE),) -> 0 | Z4: =IFERROR(VLOOKUP($A4,Data!$1:$1048576,31,FALSE),) -> 0 | AA4: =IFERROR(VLOOKUP($A4,Data!$1:$1048576,32,FALSE),) -> 0 | AB4: =IFERROR(VLOOKUP($A4,Data!$1:$1048576,33,FALSE),) -> 0
A5: =Data!A13 -> I-9 | B5: =IFERROR(VLOOKUP($A5,Data!$1:$1048576,34,FALSE),) -> 20.23 | C5: =IFERROR(VLOOKUP($A5,Data!$1:$1048576,2,FALSE),) -> Imperial | D5: =IFERROR(VLOOKUP($A5,Data!$1:$1048576,3,FALSE),) -> 2 | E5: =IFERROR(VLOOKUP($A5,Data!$1:$1048576,4,FALSE),) -> Brent | F5: =IFERROR(VLOOKUP($A5,Data!$1:$1048576,6,FALSE),) -> Spring Grain | G5: =IFERROR(VLOOKUP($A5,Data!$1:$1048576,7,FALSE),) -> Lott Rent | H5: =IFERROR(VLOOKUP($A5,Data!$1:$1048576,13,FALSE),) | I5: =IFERROR(VLOOKUP($A5,Data!$1:$1048576,14,FALSE),) -> 1.71 | J5: =IFERROR(VLOOKUP($A5,Data!$1:$1048576,15,FALSE),) -> 2.49 | K5: =IFERROR(VLOOKUP($A5,Data!$1:$1048576,16,FALSE),) -> 5.64 | L5: =IFERROR(VLOOKUP($A5,Data!$1:$1048576,17,FALSE),) -> 2.01 | M5: =IFERROR(VLOOKUP($A5,Data!$1:$1048576,18,FALSE),) -> 2.15 | N5: =IFERROR(VLOOKUP($A5,Data!$1:$1048576,19,FALSE),) -> 2.15 | O5: =IFERROR(VLOOKUP($A5,Data!$1:$1048576,20,FALSE),) -> 1.02 | P5: =IFERROR(VLOOKUP($A5,Data!$1:$1048576,21,FALSE),) -> 0 | Q5: =IFERROR(VLOOKUP($A5,Data!$1:$1048576,22,FALSE),) -> 0 | R5: =IFERROR(VLOOKUP($A5,Data!$1:$1048576,23,FALSE),) -> 0 | S5: =IFERROR(VLOOKUP($A5,Data!$1:$1048576,24,FALSE),) -> 0 | T5: =IFERROR(VLOOKUP($A5,Data!$1:$1048576,25,FALSE),) -> 0 | U5: =IFERROR(VLOOKUP($A5,Data!$1:$1048576,26,FALSE),) -> 0 | V5: =IFERROR(VLOOKUP($A5,Data!$1:$1048576,27,FALSE),) -> 0.56 | W5: =IFERROR(VLOOKUP($A5,Data!$1:$1048576,28,FALSE),) -> 1.23 | X5: =IFERROR(VLOOKUP($A5,Data!$1:$1048576,29,FALSE),) -> 0 | Y5: =IFERROR(VLOOKUP($A5,Data!$1:$1048576,30,FALSE),) -> 0 | Z5: =IFERROR(VLOOKUP($A5,Data!$1:$1048576,31,FALSE),) -> 0 | AA5: =IFERROR(VLOOKUP($A5,Data!$1:$1048576,32,FALSE),) -> 0 | AB5: =IFERROR(VLOOKUP($A5,Data!$1:$1048576,33,FALSE),) -> 0
A6: =Data!A14 -> I-10 | B6: =IFERROR(VLOOKUP($A6,Data!$1:$1048576,34,FALSE),) -> 19.8 | C6: =IFERROR(VLOOKUP($A6,Data!$1:$1048576,2,FALSE),) -> Imperial | D6: =IFERROR(VLOOKUP($A6,Data!$1:$1048576,3,FALSE),) -> 2 | E6: =IFERROR(VLOOKUP($A6,Data!$1:$1048576,4,FALSE),) -> Brent | F6: =IFERROR(VLOOKUP($A6,Data!$1:$1048576,6,FALSE),) -> Spring Grain | G6: =IFERROR(VLOOKUP($A6,Data!$1:$1048576,7,FALSE),) -> Lott Rent | H6: =IFERROR(VLOOKUP($A6,Data!$1:$1048576,13,FALSE),) | I6: =IFERROR(VLOOKUP($A6,Data!$1:$1048576,14,FALSE),) -> 1.78 | J6: =IFERROR(VLOOKUP($A6,Data!$1:$1048576,15,FALSE),) -> 2.29 | K6: =IFERROR(VLOOKUP($A6,Data!$1:$1048576,16,FALSE),) -> 5.34 | L6: =IFERROR(VLOOKUP($A6,Data!$1:$1048576,17,FALSE),) -> 1.36 | M6: =IFERROR(VLOOKUP($A6,Data!$1:$1048576,18,FALSE),) -> 2.18 | N6: =IFERROR(VLOOKUP($A6,Data!$1:$1048576,19,FALSE),) -> 2.53 | O6: =IFERROR(VLOOKUP($A6,Data!$1:$1048576,20,FALSE),) -> 0.99 | P6: =IFERROR(VLOOKUP($A6,Data!$1:$1048576,21,FALSE),) -> 0 | Q6: =IFERROR(VLOOKUP($A6,Data!$1:$1048576,22,FALSE),) -> 0 | R6: =IFERROR(VLOOKUP($A6,Data!$1:$1048576,23,FALSE),) -> 0 | S6: =IFERROR(VLOOKUP($A6,Data!$1:$1048576,24,FALSE),) -> 0 | T6: =IFERROR(VLOOKUP($A6,Data!$1:$1048576,25,FALSE),) -> 0 | U6: =IFERROR(VLOOKUP($A6,Data!$1:$1048576,26,FALSE),) -> 0 | V6: =IFERROR(VLOOKUP($A6,Data!$1:$1048576,27,FALSE),) -> 0 | W6: =IFERROR(VLOOKUP($A6,Data!$1:$1048576,28,FALSE),) -> 1.29 | X6: =IFERROR(VLOOKUP($A6,Data!$1:$1048576,29,FALSE),) -> 0.68 | Y6: =IFERROR(VLOOKUP($A6,Data!$1:$1048576,30,FALSE),) -> 0 | Z6: =IFERROR(VLOOKUP($A6,Data!$1:$1048576,31,FALSE),) -> 0 | AA6: =IFERROR(VLOOKUP($A6,Data!$1:$1048576,32,FALSE),) -> 0 | AB6: =IFERROR(VLOOKUP($A6,Data!$1:$1048576,33,FALSE),) -> 0
A7: =Data!A15 -> I-12 | B7: =IFERROR(VLOOKUP($A7,Data!$1:$1048576,34,FALSE),) -> 21.72 | C7: =IFERROR(VLOOKUP($A7,Data!$1:$1048576,2,FALSE),) -> Imperial | D7: =IFERROR(VLOOKUP($A7,Data!$1:$1048576,3,FALSE),) -> 2 | E7: =IFERROR(VLOOKUP($A7,Data!$1:$1048576,4,FALSE),) -> Brent | F7: =IFERROR(VLOOKUP($A7,Data!$1:$1048576,6,FALSE),) -> Spring Grain | G7: =IFERROR(VLOOKUP($A7,Data!$1:$1048576,7,FALSE),) -> Lott Rent | H7: =IFERROR(VLOOKUP($A7,Data!$1:$1048576,13,FALSE),) | I7: =IFERROR(VLOOKUP($A7,Data!$1:$1048576,14,FALSE),) -> 1.02 | J7: =IFERROR(VLOOKUP($A7,Data!$1:$1048576,15,FALSE),) -> 2.58 | K7: =IFERROR(VLOOKUP($A7,Data!$1:$1048576,16,FALSE),) -> 5.63 | L7: =IFERROR(VLOOKUP($A7,Data!$1:$1048576,17,FALSE),) -> 2.21 | M7: =IFERROR(VLOOKUP($A7,Data!$1:$1048576,18,FALSE),) -> 2.37 | N7: =IFERROR(VLOOKUP($A7,Data!$1:$1048576,19,FALSE),) -> 2.53 | O7: =IFERROR(VLOOKUP($A7,Data!$1:$1048576,20,FALSE),) -> 1.66 | P7: =IFERROR(VLOOKUP($A7,Data!$1:$1048576,21,FALSE),) -> 0 | Q7: =IFERROR(VLOOKUP($A7,Data!$1:$1048576,22,FALSE),) -> 0 | R7: =IFERROR(VLOOKUP($A7,Data!$1:$1048576,23,FALSE),) -> 0 | S7: =IFERROR(VLOOKUP($A7,Data!$1:$1048576,24,FALSE),) -> 0 | T7: =IFERROR(VLOOKUP($A7,Data!$1:$1048576,25,FALSE),) -> 0 | U7: =IFERROR(VLOOKUP($A7,Data!$1:$1048576,26,FALSE),) -> 0 | V7: =IFERROR(VLOOKUP($A7,Data!$1:$1048576,27,FALSE),) -> 0 | W7: =IFERROR(VLOOKUP($A7,Data!$1:$1048576,28,FALSE),) -> 1.34 | X7: =IFERROR(VLOOKUP($A7,Data!$1:$1048576,29,FALSE),) -> 0.9 | Y7: =IFERROR(VLOOKUP($A7,Data!$1:$1048576,30,FALSE),) -> 0 | Z7: =IFERROR(VLOOKUP($A7,Data!$1:$1048576,31,FALSE),) -> 0 | AA7: =IFERROR(VLOOKUP($A7,Data!$1:$1048576,32,FALSE),) -> 0 | AB7: =IFERROR(VLOOKUP($A7,Data!$1:$1048576,33,FALSE),) -> 0
A8: =Data!A16 -> I-13 | B8: =IFERROR(VLOOKUP($A8,Data!$1:$1048576,34,FALSE),) -> 20.66 | C8: =IFERROR(VLOOKUP($A8,Data!$1:$1048576,2,FALSE),) -> Imperial | D8: =IFERROR(VLOOKUP($A8,Data!$1:$1048576,3,FALSE),) -> 2 | E8: =IFERROR(VLOOKUP($A8,Data!$1:$1048576,4,FALSE),) -> Brent | F8: =IFERROR(VLOOKUP($A8,Data!$1:$1048576,6,FALSE),) -> Spring Grain | G8: =IFERROR(VLOOKUP($A8,Data!$1:$1048576,7,FALSE),) -> Lott Rent | H8: =IFERROR(VLOOKUP($A8,Data!$1:$1048576,13,FALSE),) | I8: =IFERROR(VLOOKUP($A8,Data!$1:$1048576,14,FALSE),) -> 1.7 | J8: =IFERROR(VLOOKUP($A8,Data!$1:$1048576,15,FALSE),) -> 2.57 | K8: =IFERROR(VLOOKUP($A8,Data!$1:$1048576,16,FALSE),) -> 5.52 | L8: =IFERROR(VLOOKUP($A8,Data!$1:$1048576,17,FALSE),) -> 2.02 | M8: =IFERROR(VLOOKUP($A8,Data!$1:$1048576,18,FALSE),) -> 2.15 | N8: =IFERROR(VLOOKUP($A8,Data!$1:$1048576,19,FALSE),) -> 2.2 | O8: =IFERROR(VLOOKUP($A8,Data!$1:$1048576,20,FALSE),) -> 1.43 | P8: =IFERROR(VLOOKUP($A8,Data!$1:$1048576,21,FALSE),) -> 0 | Q8: =IFERROR(VLOOKUP($A8,Data!$1:$1048576,22,FALSE),) -> 0 | R8: =IFERROR(VLOOKUP($A8,Data!$1:$1048576,23,FALSE),) -> 0 | S8: =IFERROR(VLOOKUP($A8,Data!$1:$1048576,24,FALSE),) -> 0 | T8: =IFERROR(VLOOKUP($A8,Data!$1:$1048576,25,FALSE),) -> 0 | U8: =IFERROR(VLOOKUP($A8,Data!$1:$1048576,26,FALSE),) -> 0 | V8: =IFERROR(VLOOKUP($A8,Data!$1:$1048576,27,FALSE),) -> 0 | W8: =IFERROR(VLOOKUP($A8,Data!$1:$1048576,28,FALSE),) -> 1.32 | X8: =IFERROR(VLOOKUP($A8,Data!$1:$1048576,29,FALSE),) -> 0.3 | Y8: =IFERROR(VLOOKUP($A8,Data!$1:$1048576,30,FALSE),) -> 0 | Z8: =IFERROR(VLOOKUP($A8,Data!$1:$1048576,31,FALSE),) -> 0 | AA8: =IFERROR(VLOOKUP($A8,Data!$1:$1048576,32,FALSE),) -> 0 | AB8: =IFERROR(VLOOKUP($A8,Data!$1:$1048576,33,FALSE),) -> 0
A9: =Data!A17 -> I-18 | B9: =IFERROR(VLOOKUP($A9,Data!$1:$1048576,34,FALSE),) -> 23.29 | C9: =IFERROR(VLOOKUP($A9,Data!$1:$1048576,2,FALSE),) -> Imperial | D9: =IFERROR(VLOOKUP($A9,Data!$1:$1048576,3,FALSE),) -> 2 | E9: =IFERROR(VLOOKUP($A9,Data!$1:$1048576,4,FALSE),) -> Brent | F9: =IFERROR(VLOOKUP($A9,Data!$1:$1048576,6,FALSE),) -> Spring Grain | G9: =IFERROR(VLOOKUP($A9,Data!$1:$1048576,7,FALSE),) -> Lott Rent | H9: =IFERROR(VLOOKUP($A9,Data!$1:$1048576,13,FALSE),) | I9: =IFERROR(VLOOKUP($A9,Data!$1:$1048576,14,FALSE),) -> 1.72 | J9: =IFERROR(VLOOKUP($A9,Data!$1:$1048576,15,FALSE),) -> 2.39 | K9: =IFERROR(VLOOKUP($A9,Data!$1:$1048576,16,FALSE),) -> 5.88 | L9: =IFERROR(VLOOKUP($A9,Data!$1:$1048576,17,FALSE),) -> 2.28 | M9: =IFERROR(VLOOKUP($A9,Data!$1:$1048576,18,FALSE),) -> 2.61 | N9: =IFERROR(VLOOKUP($A9,Data!$1:$1048576,19,FALSE),) -> 2.65 | O9: =IFERROR(VLOOKUP($A9,Data!$1:$1048576,20,FALSE),) -> 1.68 | P9: =IFERROR(VLOOKUP($A9,Data!$1:$1048576,21,FALSE),) -> 0 | Q9: =IFERROR(VLOOKUP($A9,Data!$1:$1048576,22,FALSE),) -> 0 | R9: =IFERROR(VLOOKUP($A9,Data!$1:$1048576,23,FALSE),) -> 0 | S9: =IFERROR(VLOOKUP($A9,Data!$1:$1048576,24,FALSE),) -> 0 | T9: =IFERROR(VLOOKUP($A9,Data!$1:$1048576,25,FALSE),) -> 0 | U9: =IFERROR(VLOOKUP($A9,Data!$1:$1048576,26,FALSE),) -> 0 | V9: =IFERROR(VLOOKUP($A9,Data!$1:$1048576,27,FALSE),) -> 0 | W9: =IFERROR(VLOOKUP($A9,Data!$1:$1048576,28,FALSE),) -> 0.59 | X9: =IFERROR(VLOOKUP($A9,Data!$1:$1048576,29,FALSE),) -> 2.11 | Y9: =IFERROR(VLOOKUP($A9,Data!$1:$1048576,30,FALSE),) -> 0 | Z9: =IFERROR(VLOOKUP($A9,Data!$1:$1048576,31,FALSE),) -> 0 | AA9: =IFERROR(VLOOKUP($A9,Data!$1:$1048576,32,FALSE),) -> 0 | AB9: =IFERROR(VLOOKUP($A9,Data!$1:$1048576,33,FALSE),) -> 0
A10: =Data!A18 -> I-19 | B10: =IFERROR(VLOOKUP($A10,Data!$1:$1048576,34,FALSE),) -> 22.63 | C10: =IFERROR(VLOOKUP($A10,Data!$1:$1048576,2,FALSE),) -> Imperial | D10: =IFERROR(VLOOKUP($A10,Data!$1:$1048576,3,FALSE),) -> 2 | E10: =IFERROR(VLOOKUP($A10,Data!$1:$1048576,4,FALSE),) -> Brent | F10: =IFERROR(VLOOKUP($A10,Data!$1:$1048576,6,FALSE),) -> Spring Grain | G10: =IFERROR(VLOOKUP($A10,Data!$1:$1048576,7,FALSE),) -> Lott Rent | H10: =IFERROR(VLOOKUP($A10,Data!$1:$1048576,13,FALSE),) | I10: =IFERROR(VLOOKUP($A10,Data!$1:$1048576,14,FALSE),) -> 1.75 | J10: =IFERROR(VLOOKUP($A10,Data!$1:$1048576,15,FALSE),) -> 2.51 | K10: =IFERROR(VLOOKUP($A10,Data!$1:$1048576,16,FALSE),) -> 6.21 | L10: =IFERROR(VLOOKUP($A10,Data!$1:$1048576,17,FALSE),) -> 2.49 | M10: =IFERROR(VLOOKUP($A10,Data!$1:$1048576,18,FALSE),) -> 2.61 | N10: =IFERROR(VLOOKUP($A10,Data!$1:$1048576,19,FALSE),) -> 2.62 | O10: =IFERROR(VLOOKUP($A10,Data!$1:$1048576,20,FALSE),) -> 1.7 | P10: =IFERROR(VLOOKUP($A10,Data!$1:$1048576,21,FALSE),) -> 0 | Q10: =IFERROR(VLOOKUP($A10,Data!$1:$1048576,22,FALSE),) -> 0 | R10: =IFERROR(VLOOKUP($A10,Data!$1:$1048576,23,FALSE),) -> 0 | S10: =IFERROR(VLOOKUP($A10,Data!$1:$1048576,24,FALSE),) -> 0 | T10: =IFERROR(VLOOKUP($A10,Data!$1:$1048576,25,FALSE),) -> 0 | U10: =IFERROR(VLOOKUP($A10,Data!$1:$1048576,26,FALSE),) -> 0 | V10: =IFERROR(VLOOKUP($A10,Data!$1:$1048576,27,FALSE),) -> 0 | W10: =IFERROR(VLOOKUP($A10,Data!$1:$1048576,28,FALSE),) -> 1.08 | X10: =IFERROR(VLOOKUP($A10,Data!$1:$1048576,29,FALSE),) -> 1.05 | Y10: =IFERROR(VLOOKUP($A10,Data!$1:$1048576,30,FALSE),) -> 0 | Z10: =IFERROR(VLOOKUP($A10,Data!$1:$1048576,31,FALSE),) -> 0 | AA10: =IFERROR(VLOOKUP($A10,Data!$1:$1048576,32,FALSE),) -> 0 | AB10: =IFERROR(VLOOKUP($A10,Data!$1:$1048576,33,FALSE),) -> 0
A11: =Data!A19 -> I-22 | B11: =IFERROR(VLOOKUP($A11,Data!$1:$1048576,34,FALSE),) -> 19.57 | C11: =IFERROR(VLOOKUP($A11,Data!$1:$1048576,2,FALSE),) -> Imperial | D11: =IFERROR(VLOOKUP($A11,Data!$1:$1048576,3,FALSE),) -> 2 | E11: =IFERROR(VLOOKUP($A11,Data!$1:$1048576,4,FALSE),) -> Brent | F11: =IFERROR(VLOOKUP($A11,Data!$1:$1048576,6,FALSE),) -> Spring Grain | G11: =IFERROR(VLOOKUP($A11,Data!$1:$1048576,7,FALSE),) -> Lott Rent | H11: =IFERROR(VLOOKUP($A11,Data!$1:$1048576,13,FALSE),) | I11: =IFERROR(VLOOKUP($A11,Data!$1:$1048576,14,FALSE),) -> 1.69 | J11: =IFERROR(VLOOKUP($A11,Data!$1:$1048576,15,FALSE),) -> 2.3 | K11: =IFERROR(VLOOKUP($A11,Data!$1:$1048576,16,FALSE),) -> 5.54 | L11: =IFERROR(VLOOKUP($A11,Data!$1:$1048576,17,FALSE),) -> 2.54 | M11: =IFERROR(VLOOKUP($A11,Data!$1:$1048576,18,FALSE),) -> 2.54 | N11: =IFERROR(VLOOKUP($A11,Data!$1:$1048576,19,FALSE),) -> 2.08 | O11: =IFERROR(VLOOKUP($A11,Data!$1:$1048576,20,FALSE),) -> 0 | P11: =IFERROR(VLOOKUP($A11,Data!$1:$1048576,21,FALSE),) -> 0 | Q11: =IFERROR(VLOOKUP($A11,Data!$1:$1048576,22,FALSE),) -> 0 | R11: =IFERROR(VLOOKUP($A11,Data!$1:$1048576,23,FALSE),) -> 0 | S11: =IFERROR(VLOOKUP($A11,Data!$1:$1048576,24,FALSE),) -> 0 | T11: =IFERROR(VLOOKUP($A11,Data!$1:$1048576,25,FALSE),) -> 0.54 | U11: =IFERROR(VLOOKUP($A11,Data!$1:$1048576,26,FALSE),) -> 1.03 | V11: =IFERROR(VLOOKUP($A11,Data!$1:$1048576,27,FALSE),) -> 0 | W11: =IFERROR(VLOOKUP($A11,Data!$1:$1048576,28,FALSE),) -> 0 | X11: =IFERROR(VLOOKUP($A11,Data!$1:$1048576,29,FALSE),) -> 0 | Y11: =IFERROR(VLOOKUP($A11,Data!$1:$1048576,30,FALSE),) -> 0 | Z11: =IFERROR(VLOOKUP($A11,Data!$1:$1048576,31,FALSE),) -> 0 | AA11: =IFERROR(VLOOKUP($A11,Data!$1:$1048576,32,FALSE),) -> 0 | AB11: =IFERROR(VLOOKUP($A11,Data!$1:$1048576,33,FALSE),) -> 0
A12: =Data!A20 -> I-23 | B12: =IFERROR(VLOOKUP($A12,Data!$1:$1048576,34,FALSE),) -> 18.33 | C12: =IFERROR(VLOOKUP($A12,Data!$1:$1048576,2,FALSE),) -> Imperial | D12: =IFERROR(VLOOKUP($A12,Data!$1:$1048576,3,FALSE),) -> 2 | E12: =IFERROR(VLOOKUP($A12,Data!$1:$1048576,4,FALSE),) -> Brent | F12: =IFERROR(VLOOKUP($A12,Data!$1:$1048576,6,FALSE),) -> Spring Grain | G12: =IFERROR(VLOOKUP($A12,Data!$1:$1048576,7,FALSE),) -> Lott Rent | H12: =IFERROR(VLOOKUP($A12,Data!$1:$1048576,13,FALSE),) | I12: =IFERROR(VLOOKUP($A12,Data!$1:$1048576,14,FALSE),) -> 1.11 | J12: =IFERROR(VLOOKUP($A12,Data!$1:$1048576,15,FALSE),) -> 2.55 | K12: =IFERROR(VLOOKUP($A12,Data!$1:$1048576,16,FALSE),) -> 5.6 | L12: =IFERROR(VLOOKUP($A12,Data!$1:$1048576,17,FALSE),) -> 2.34 | M12: =IFERROR(VLOOKUP($A12,Data!$1:$1048576,18,FALSE),) -> 2.4 | N12: =IFERROR(VLOOKUP($A12,Data!$1:$1048576,19,FALSE),) -> 1.82 | O12: =IFERROR(VLOOKUP($A12,Data!$1:$1048576,20,FALSE),) -> 0 | P12: =IFERROR(VLOOKUP($A12,Data!$1:$1048576,21,FALSE),) -> 0 | Q12: =IFERROR(VLOOKUP($A12,Data!$1:$1048576,22,FALSE),) -> 0 | R12: =IFERROR(VLOOKUP($A12,Data!$1:$1048576,23,FALSE),) -> 0 | S12: =IFERROR(VLOOKUP($A12,Data!$1:$1048576,24,FALSE),) -> 0 | T12: =IFERROR(VLOOKUP($A12,Data!$1:$1048576,25,FALSE),) -> 0.22 | U12: =IFERROR(VLOOKUP($A12,Data!$1:$1048576,26,FALSE),) -> 0.96 | V12: =IFERROR(VLOOKUP($A12,Data!$1:$1048576,27,FALSE),) -> 0 | W12: =IFERROR(VLOOKUP($A12,Data!$1:$1048576,28,FALSE),) -> 0 | X12: =IFERROR(VLOOKUP($A12,Data!$1:$1048576,29,FALSE),) -> 0 | Y12: =IFERROR(VLOOKUP($A12,Data!$1:$1048576,30,FALSE),) -> 0 | Z12: =IFERROR(VLOOKUP($A12,Data!$1:$1048576,31,FALSE),) -> 0 | AA12: =IFERROR(VLOOKUP($A12,Data!$1:$1048576,32,FALSE),) -> 0 | AB12: =IFERROR(VLOOKUP($A12,Data!$1:$1048576,33,FALSE),) -> 0
A13: =Data!A22 -> I-13D | B13: =IFERROR(VLOOKUP($A13,Data!$1:$1048576,34,FALSE),) -> 0 | C13: =IFERROR(VLOOKUP($A13,Data!$1:$1048576,2,FALSE),) -> Imperial | D13: =IFERROR(VLOOKUP($A13,Data!$1:$1048576,3,FALSE),) -> 2 | E13: =IFERROR(VLOOKUP($A13,Data!$1:$1048576,4,FALSE),) -> Brent | F13: =IFERROR(VLOOKUP($A13,Data!$1:$1048576,6,FALSE),) -> Spring Grain | G13: =IFERROR(VLOOKUP($A13,Data!$1:$1048576,7,FALSE),) -> Lott Rent | H13: =IFERROR(VLOOKUP($A13,Data!$1:$1048576,13,FALSE),) -> 0 | I13: =IFERROR(VLOOKUP($A13,Data!$1:$1048576,14,FALSE),) -> 0 | J13: =IFERROR(VLOOKUP($A13,Data!$1:$1048576,15,FALSE),) -> 0 | K13: =IFERROR(VLOOKUP($A13,Data!$1:$1048576,16,FALSE),) -> 0 | L13: =IFERROR(VLOOKUP($A13,Data!$1:$1048576,17,FALSE),) -> 0 | M13: =IFERROR(VLOOKUP($A13,Data!$1:$1048576,18,FALSE),) -> 0 | N13: =IFERROR(VLOOKUP($A13,Data!$1:$1048576,19,FALSE),) -> 0 | O13: =IFERROR(VLOOKUP($A13,Data!$1:$1048576,20,FALSE),) -> 0 | P13: =IFERROR(VLOOKUP($A13,Data!$1:$1048576,21,FALSE),) -> 0 | Q13: =IFERROR(VLOOKUP($A13,Data!$1:$1048576,22,FALSE),) -> 0 | R13: =IFERROR(VLOOKUP($A13,Data!$1:$1048576,23,FALSE),) -> 0 | S13: =IFERROR(VLOOKUP($A13,Data!$1:$1048576,24,FALSE),) -> 0 | T13: =IFERROR(VLOOKUP($A13,Data!$1:$1048576,25,FALSE),) -> 0 | U13: =IFERROR(VLOOKUP($A13,Data!$1:$1048576,26,FALSE),) -> 0 | V13: =IFERROR(VLOOKUP($A13,Data!$1:$1048576,27,FALSE),) -> 0 | W13: =IFERROR(VLOOKUP($A13,Data!$1:$1048576,28,FALSE),) -> 0 | X13: =IFERROR(VLOOKUP($A13,Data!$1:$1048576,29,FALSE),) -> 0 | Y13: =IFERROR(VLOOKUP($A13,Data!$1:$1048576,30,FALSE),) -> 0 | Z13: =IFERROR(VLOOKUP($A13,Data!$1:$1048576,31,FALSE),) -> 0 | AA13: =IFERROR(VLOOKUP($A13,Data!$1:$1048576,32,FALSE),) -> 0 | AB13: =IFERROR(VLOOKUP($A13,Data!$1:$1048576,33,FALSE),) -> 0

Sheet Group 10
A1: =E4 -> Brent
A2: Field | B2: YTD | C2: Farm | D2: Group | E2: Manager | F2: Crop | G2: Variety | H2: =Dates!F2 -> 45453 | I2: =Dates!G2 -> 45460 | J2: =Dates!H2 -> 45467 | K2: =Dates!I2 -> 45474 | L2: =Dates!J2 -> 45481 | M2: =Dates!K2 -> 45488 | N2: =Dates!L2 -> 45495 | O2: =Dates!M2 -> 45502 | ... AB2: =Dates!Z2 -> 45593
A3: Rain | B3: =+SUM(H3:AB3) -> 0.23 | H3: ='Rain Totals'!H2 -> 0 | I3: ='Rain Totals'!I2 -> 0.03 | J3: ='Rain Totals'!J2 -> 0 | K3: ='Rain Totals'!K2 -> 0 | L3: ='Rain Totals'!L2 -> 0.2 | M3: ='Rain Totals'!M2 -> 0 | N3: ='Rain Totals'!N2 -> 0 | O3: ='Rain Totals'!O2 -> 0 | ... AB3: ='Rain Totals'!AB2 -> 0
A4: =Data!A96 -> .ET 10 | B4: =IFERROR(VLOOKUP($A4,Data!$1:$1048576,34,FALSE),) -> 21.75 | C4: =IFERROR(VLOOKUP($A4,Data!$1:$1048576,2,FALSE),) -> Imperial | D4: =IFERROR(VLOOKUP($A4,Data!$1:$1048576,3,FALSE),) -> 10 | E4: =IFERROR(VLOOKUP($A4,Data!$1:$1048576,4,FALSE),) -> Brent | F4: =IFERROR(VLOOKUP($A4,Data!$1:$1048576,6,FALSE),) -> Spring Grain | G4: =IFERROR(VLOOKUP($A4,Data!$1:$1048576,7,FALSE),) -> Cannon Rent | H4: =IFERROR(VLOOKUP($A4,Data!$1:$1048576,13,FALSE),) -> 2.24 | I4: =IFERROR(VLOOKUP($A4,Data!$1:$1048576,14,FALSE),) -> 2.03 | J4: =IFERROR(VLOOKUP($A4,Data!$1:$1048576,15,FALSE),) -> 1.99 | K4: =IFERROR(VLOOKUP($A4,Data!$1:$1048576,16,FALSE),) -> 1.94 | L4: =IFERROR(VLOOKUP($A4,Data!$1:$1048576,17,FALSE),) -> 1.68 | M4: =IFERROR(VLOOKUP($A4,Data!$1:$1048576,18,FALSE),) -> 1.69 | N4: =IFERROR(VLOOKUP($A4,Data!$1:$1048576,19,FALSE),) -> 1.77 | O4: =IFERROR(VLOOKUP($A4,Data!$1:$1048576,20,FALSE),) -> 1.82 | P4: =IFERROR(VLOOKUP($A4,Data!$1:$1048576,21,FALSE),) -> 1.61 | Q4: =IFERROR(VLOOKUP($A4,Data!$1:$1048576,22,FALSE),) -> 1.22 | R4: =IFERROR(VLOOKUP($A4,Data!$1:$1048576,23,FALSE),) -> 0.13 | S4: =IFERROR(VLOOKUP($A4,Data!$1:$1048576,24,FALSE),) -> 0 | T4: =IFERROR(VLOOKUP($A4,Data!$1:$1048576,25,FALSE),) -> 0 | U4: =IFERROR(VLOOKUP($A4,Data!$1:$1048576,26,FALSE),) -> 0 | V4: =IFERROR(VLOOKUP($A4,Data!$1:$1048576,27,FALSE),) -> 0 | W4: =IFERROR(VLOOKUP($A4,Data!$1:$1048576,28,FALSE),) -> 0 | X4: =IFERROR(VLOOKUP($A4,Data!$1:$1048576,29,FALSE),) -> 0 | Y4: =IFERROR(VLOOKUP($A4,Data!$1:$1048576,30,FALSE),) -> 0 | Z4: =IFERROR(VLOOKUP($A4,Data!$1:$1048576,31,FALSE),) -> 0 | AA4: =IFERROR(VLOOKUP($A4,Data!$1:$1048576,32,FALSE),) -> 0 | AB4: =IFERROR(VLOOKUP($A4,Data!$1:$1048576,33,FALSE),) -> 0
A5: =Data!A97 -> O-1 | B5: =IFERROR(VLOOKUP($A5,Data!$1:$1048576,34,FALSE),) -> 24.34 | C5: =IFERROR(VLOOKUP($A5,Data!$1:$1048576,2,FALSE),) -> Imperial | D5: =IFERROR(VLOOKUP($A5,Data!$1:$1048576,3,FALSE),) -> 10 | E5: =IFERROR(VLOOKUP($A5,Data!$1:$1048576,4,FALSE),) -> Brent | F5: =IFERROR(VLOOKUP($A5,Data!$1:$1048576,6,FALSE),) -> Spring Grain | G5: =IFERROR(VLOOKUP($A5,Data!$1:$1048576,7,FALSE),) -> Cannon Rent | H5: =IFERROR(VLOOKUP($A5,Data!$1:$1048576,13,FALSE),) | I5: =IFERROR(VLOOKUP($A5,Data!$1:$1048576,14,FALSE),) -> 1.29 | J5: =IFERROR(VLOOKUP($A5,Data!$1:$1048576,15,FALSE),) -> 0.78 | K5: =IFERROR(VLOOKUP($A5,Data!$1:$1048576,16,FALSE),) -> 2.4 | L5: =IFERROR(VLOOKUP($A5,Data!$1:$1048576,17,FALSE),) -> 2.57 | M5: =IFERROR(VLOOKUP($A5,Data!$1:$1048576,18,FALSE),) -> 2.49 | N5: =IFERROR(VLOOKUP($A5,Data!$1:$1048576,19,FALSE),) -> 1.77 | O5: =IFERROR(VLOOKUP($A5,Data!$1:$1048576,20,FALSE),) -> 2.38 | P5: =IFERROR(VLOOKUP($A5,Data!$1:$1048576,21,FALSE),) -> 1.44 | Q5: =IFERROR(VLOOKUP($A5,Data!$1:$1048576,22,FALSE),) -> 1.72 | R5: =IFERROR(VLOOKUP($A5,Data!$1:$1048576,23,FALSE),) -> 1.36 | S5: =IFERROR(VLOOKUP($A5,Data!$1:$1048576,24,FALSE),) -> 1.66 | T5: =IFERROR(VLOOKUP($A5,Data!$1:$1048576,25,FALSE),) -> 2.02 | U5: =IFERROR(VLOOKUP($A5,Data!$1:$1048576,26,FALSE),) -> 1.68 | V5: =IFERROR(VLOOKUP($A5,Data!$1:$1048576,27,FALSE),) -> 0 | W5: =IFERROR(VLOOKUP($A5,Data!$1:$1048576,28,FALSE),) -> 0 | X5: =IFERROR(VLOOKUP($A5,Data!$1:$1048576,29,FALSE),) -> 0 | Y5: =IFERROR(VLOOKUP($A5,Data!$1:$1048576,30,FALSE),) -> 0 | Z5: =IFERROR(VLOOKUP($A5,Data!$1:$1048576,31,FALSE),) -> 0 | AA5: =IFERROR(VLOOKUP($A5,Data!$1:$1048576,32,FALSE),) -> 0 | AB5: =IFERROR(VLOOKUP($A5,Data!$1:$1048576,33,FALSE),) -> 0
A6: =Data!A98 -> O-2 | B6: =IFERROR(VLOOKUP($A6,Data!$1:$1048576,34,FALSE),) -> 22.74 | C6: =IFERROR(VLOOKUP($A6,Data!$1:$1048576,2,FALSE),) -> Imperial | D6: =IFERROR(VLOOKUP($A6,Data!$1:$1048576,3,FALSE),) -> 10 | E6: =IFERROR(VLOOKUP($A6,Data!$1:$1048576,4,FALSE),) -> Brent | F6: =IFERROR(VLOOKUP($A6,Data!$1:$1048576,6,FALSE),) -> Spring Grain | G6: =IFERROR(VLOOKUP($A6,Data!$1:$1048576,7,FALSE),) -> Cannon Rent | H6: =IFERROR(VLOOKUP($A6,Data!$1:$1048576,13,FALSE),) | I6: =IFERROR(VLOOKUP($A6,Data!$1:$1048576,14,FALSE),) -> 1.31 | J6: =IFERROR(VLOOKUP($A6,Data!$1:$1048576,15,FALSE),) -> 0.77 | K6: =IFERROR(VLOOKUP($A6,Data!$1:$1048576,16,FALSE),) -> 2.39 | L6: =IFERROR(VLOOKUP($A6,Data!$1:$1048576,17,FALSE),) -> 2.53 | M6: =IFERROR(VLOOKUP($A6,Data!$1:$1048576,18,FALSE),) -> 2.56 | N6: =IFERROR(VLOOKUP($A6,Data!$1:$1048576,19,FALSE),) -> 1.67 | O6: =IFERROR(VLOOKUP($A6,Data!$1:$1048576,20,FALSE),) -> 1.93 | P6: =IFERROR(VLOOKUP($A6,Data!$1:$1048576,21,FALSE),) -> 1.81 | Q6: =IFERROR(VLOOKUP($A6,Data!$1:$1048576,22,FALSE),) -> 1.77 | R6: =IFERROR(VLOOKUP($A6,Data!$1:$1048576,23,FALSE),) -> 1.2 | S6: =IFERROR(VLOOKUP($A6,Data!$1:$1048576,24,FALSE),) -> 1.62 | T6: =IFERROR(VLOOKUP($A6,Data!$1:$1048576,25,FALSE),) -> 1.64 | U6: =IFERROR(VLOOKUP($A6,Data!$1:$1048576,26,FALSE),) -> 0.82 | V6: =IFERROR(VLOOKUP($A6,Data!$1:$1048576,27,FALSE),) -> 0 | W6: =IFERROR(VLOOKUP($A6,Data!$1:$1048576,28,FALSE),) -> 0 | X6: =IFERROR(VLOOKUP($A6,Data!$1:$1048576,29,FALSE),) -> 0 | Y6: =IFERROR(VLOOKUP($A6,Data!$1:$1048576,30,FALSE),) -> 0 | Z6: =IFERROR(VLOOKUP($A6,Data!$1:$1048576,31,FALSE),) -> 0 | AA6: =IFERROR(VLOOKUP($A6,Data!$1:$1048576,32,FALSE),) -> 0 | AB6: =IFERROR(VLOOKUP($A6,Data!$1:$1048576,33,FALSE),) -> 0
A7: =Data!A99 -> O-3 | B7: =IFERROR(VLOOKUP($A7,Data!$1:$1048576,34,FALSE),) -> 22.81 | C7: =IFERROR(VLOOKUP($A7,Data!$1:$1048576,2,FALSE),) -> Imperial | D7: =IFERROR(VLOOKUP($A7,Data!$1:$1048576,3,FALSE),) -> 10 | E7: =IFERROR(VLOOKUP($A7,Data!$1:$1048576,4,FALSE),) -> Brent | F7: =IFERROR(VLOOKUP($A7,Data!$1:$1048576,6,FALSE),) -> Spring Grain | G7: =IFERROR(VLOOKUP($A7,Data!$1:$1048576,7,FALSE),) -> Cannon Rent | H7: =IFERROR(VLOOKUP($A7,Data!$1:$1048576,13,FALSE),) | I7: =IFERROR(VLOOKUP($A7,Data!$1:$1048576,14,FALSE),) -> 1.28 | J7: =IFERROR(VLOOKUP($A7,Data!$1:$1048576,15,FALSE),) -> 0.7 | K7: =IFERROR(VLOOKUP($A7,Data!$1:$1048576,16,FALSE),) -> 2.22 | L7: =IFERROR(VLOOKUP($A7,Data!$1:$1048576,17,FALSE),) -> 2.3 | M7: =IFERROR(VLOOKUP($A7,Data!$1:$1048576,18,FALSE),) -> 2.35 | N7: =IFERROR(VLOOKUP($A7,Data!$1:$1048576,19,FALSE),) -> 1.73 | O7: =IFERROR(VLOOKUP($A7,Data!$1:$1048576,20,FALSE),) -> 2.19 | P7: =IFERROR(VLOOKUP($A7,Data!$1:$1048576,21,FALSE),) -> 1.63 | Q7: =IFERROR(VLOOKUP($A7,Data!$1:$1048576,22,FALSE),) -> 2.01 | R7: =IFERROR(VLOOKUP($A7,Data!$1:$1048576,23,FALSE),) -> 1.65 | S7: =IFERROR(VLOOKUP($A7,Data!$1:$1048576,24,FALSE),) -> 1.42 | T7: =IFERROR(VLOOKUP($A7,Data!$1:$1048576,25,FALSE),) -> 1.47 | U7: =IFERROR(VLOOKUP($A7,Data!$1:$1048576,26,FALSE),) -> 0.86 | V7: =IFERROR(VLOOKUP($A7,Data!$1:$1048576,27,FALSE),) -> 0 | W7: =IFERROR(VLOOKUP($A7,Data!$1:$1048576,28,FALSE),) -> 0 | X7: =IFERROR(VLOOKUP($A7,Data!$1:$1048576,29,FALSE),) -> 0 | Y7: =IFERROR(VLOOKUP($A7,Data!$1:$1048576,30,FALSE),) -> 0 | Z7: =IFERROR(VLOOKUP($A7,Data!$1:$1048576,31,FALSE),) -> 0 | AA7: =IFERROR(VLOOKUP($A7,Data!$1:$1048576,32,FALSE),) -> 0 | AB7: =IFERROR(VLOOKUP($A7,Data!$1:$1048576,33,FALSE),) -> 0
A8: =Data!A100 -> O-4 | B8: =IFERROR(VLOOKUP($A8,Data!$1:$1048576,34,FALSE),) -> 21.11 | C8: =IFERROR(VLOOKUP($A8,Data!$1:$1048576,2,FALSE),) -> Imperial | D8: =IFERROR(VLOOKUP($A8,Data!$1:$1048576,3,FALSE),) -> 10 | E8: =IFERROR(VLOOKUP($A8,Data!$1:$1048576,4,FALSE),) -> Brent | F8: =IFERROR(VLOOKUP($A8,Data!$1:$1048576,6,FALSE),) -> Spring Grain | G8: =IFERROR(VLOOKUP($A8,Data!$1:$1048576,7,FALSE),) -> Cannon Rent | H8: =IFERROR(VLOOKUP($A8,Data!$1:$1048576,13,FALSE),) | I8: =IFERROR(VLOOKUP($A8,Data!$1:$1048576,14,FALSE),) -> 1.39 | J8: =IFERROR(VLOOKUP($A8,Data!$1:$1048576,15,FALSE),) -> 0.74 | K8: =IFERROR(VLOOKUP($A8,Data!$1:$1048576,16,FALSE),) -> 2.35 | L8: =IFERROR(VLOOKUP($A8,Data!$1:$1048576,17,FALSE),) -> 2.38 | M8: =IFERROR(VLOOKUP($A8,Data!$1:$1048576,18,FALSE),) -> 2.47 | N8: =IFERROR(VLOOKUP($A8,Data!$1:$1048576,19,FALSE),) -> 1.88 | O8: =IFERROR(VLOOKUP($A8,Data!$1:$1048576,20,FALSE),) -> 2.35 | P8: =IFERROR(VLOOKUP($A8,Data!$1:$1048576,21,FALSE),) -> 1.75 | Q8: =IFERROR(VLOOKUP($A8,Data!$1:$1048576,22,FALSE),) -> 1.8 | R8: =IFERROR(VLOOKUP($A8,Data!$1:$1048576,23,FALSE),) -> 0 | S8: =IFERROR(VLOOKUP($A8,Data!$1:$1048576,24,FALSE),) -> 0 | T8: =IFERROR(VLOOKUP($A8,Data!$1:$1048576,25,FALSE),) -> 1.85 | U8: =IFERROR(VLOOKUP($A8,Data!$1:$1048576,26,FALSE),) -> 0.94 | V8: =IFERROR(VLOOKUP($A8,Data!$1:$1048576,27,FALSE),) -> 0 | W8: =IFERROR(VLOOKUP($A8,Data!$1:$1048576,28,FALSE),) -> 0 | X8: =IFERROR(VLOOKUP($A8,Data!$1:$1048576,29,FALSE),) -> 0 | Y8: =IFERROR(VLOOKUP($A8,Data!$1:$1048576,30,FALSE),) -> 0 | Z8: =IFERROR(VLOOKUP($A8,Data!$1:$1048576,31,FALSE),) -> 0 | AA8: =IFERROR(VLOOKUP($A8,Data!$1:$1048576,32,FALSE),) -> 0 | AB8: =IFERROR(VLOOKUP($A8,Data!$1:$1048576,33,FALSE),) -> 0
A9: =Data!A101 -> 0 | B9: =IFERROR(VLOOKUP($A9,Data!$1:$1048576,34,FALSE),) -> 0 | C9: =IFERROR(VLOOKUP($A9,Data!$1:$1048576,2,FALSE),) -> 0 | D9: =IFERROR(VLOOKUP($A9,Data!$1:$1048576,3,FALSE),) -> 0 | E9: =IFERROR(VLOOKUP($A9,Data!$1:$1048576,4,FALSE),) -> 0 | F9: =IFERROR(VLOOKUP($A9,Data!$1:$1048576,6,FALSE),) -> 0 | G9: =IFERROR(VLOOKUP($A9,Data!$1:$1048576,7,FALSE),) -> 0 | H9: =IFERROR(VLOOKUP($A9,Data!$1:$1048576,13,FALSE),) -> 0 | I9: =IFERROR(VLOOKUP($A9,Data!$1:$1048576,14,FALSE),) -> 0 | J9: =IFERROR(VLOOKUP($A9,Data!$1:$1048576,15,FALSE),) -> 0 | K9: =IFERROR(VLOOKUP($A9,Data!$1:$1048576,16,FALSE),) -> 0 | L9: =IFERROR(VLOOKUP($A9,Data!$1:$1048576,17,FALSE),) -> 0 | M9: =IFERROR(VLOOKUP($A9,Data!$1:$1048576,18,FALSE),) -> 0 | N9: =IFERROR(VLOOKUP($A9,Data!$1:$1048576,19,FALSE),) -> 0 | O9: =IFERROR(VLOOKUP($A9,Data!$1:$1048576,20,FALSE),) -> 0 | P9: =IFERROR(VLOOKUP($A9,Data!$1:$1048576,21,FALSE),) -> 0 | Q9: =IFERROR(VLOOKUP($A9,Data!$1:$1048576,22,FALSE),) -> 0 | R9: =IFERROR(VLOOKUP($A9,Data!$1:$1048576,23,FALSE),) -> 0 | S9: =IFERROR(VLOOKUP($A9,Data!$1:$1048576,24,FALSE),) -> 0 | T9: =IFERROR(VLOOKUP($A9,Data!$1:$1048576,25,FALSE),) -> 0 | U9: =IFERROR(VLOOKUP($A9,Data!$1:$1048576,26,FALSE),) -> 0 | V9: =IFERROR(VLOOKUP($A9,Data!$1:$1048576,27,FALSE),) -> 0 | W9: =IFERROR(VLOOKUP($A9,Data!$1:$1048576,28,FALSE),) -> 0 | X9: =IFERROR(VLOOKUP($A9,Data!$1:$1048576,29,FALSE),) -> 0 | Y9: =IFERROR(VLOOKUP($A9,Data!$1:$1048576,30,FALSE),) -> 0 | Z9: =IFERROR(VLOOKUP($A9,Data!$1:$1048576,31,FALSE),) -> 0 | AA9: =IFERROR(VLOOKUP($A9,Data!$1:$1048576,32,FALSE),) -> 0 | AB9: =IFERROR(VLOOKUP($A9,Data!$1:$1048576,33,FALSE),) -> 0
A10: =Data!A102 -> 0 | B10: =IFERROR(VLOOKUP($A10,Data!$1:$1048576,34,FALSE),) -> 0 | C10: =IFERROR(VLOOKUP($A10,Data!$1:$1048576,2,FALSE),) -> 0 | D10: =IFERROR(VLOOKUP($A10,Data!$1:$1048576,3,FALSE),) -> 0 | E10: =IFERROR(VLOOKUP($A10,Data!$1:$1048576,4,FALSE),) -> 0 | F10: =IFERROR(VLOOKUP($A10,Data!$1:$1048576,6,FALSE),) -> 0 | G10: =IFERROR(VLOOKUP($A10,Data!$1:$1048576,7,FALSE),) -> 0 | H10: =IFERROR(VLOOKUP($A10,Data!$1:$1048576,13,FALSE),) -> 0 | I10: =IFERROR(VLOOKUP($A10,Data!$1:$1048576,14,FALSE),) -> 0 | J10: =IFERROR(VLOOKUP($A10,Data!$1:$1048576,15,FALSE),) -> 0 | K10: =IFERROR(VLOOKUP($A10,Data!$1:$1048576,16,FALSE),) -> 0 | L10: =IFERROR(VLOOKUP($A10,Data!$1:$1048576,17,FALSE),) -> 0 | M10: =IFERROR(VLOOKUP($A10,Data!$1:$1048576,18,FALSE),) -> 0 | N10: =IFERROR(VLOOKUP($A10,Data!$1:$1048576,19,FALSE),) -> 0 | O10: =IFERROR(VLOOKUP($A10,Data!$1:$1048576,20,FALSE),) -> 0 | P10: =IFERROR(VLOOKUP($A10,Data!$1:$1048576,21,FALSE),) -> 0 | Q10: =IFERROR(VLOOKUP($A10,Data!$1:$1048576,22,FALSE),) -> 0 | R10: =IFERROR(VLOOKUP($A10,Data!$1:$1048576,23,FALSE),) -> 0 | S10: =IFERROR(VLOOKUP($A10,Data!$1:$1048576,24,FALSE),) -> 0 | T10: =IFERROR(VLOOKUP($A10,Data!$1:$1048576,25,FALSE),) -> 0 | U10: =IFERROR(VLOOKUP($A10,Data!$1:$1048576,26,FALSE),) -> 0 | V10: =IFERROR(VLOOKUP($A10,Data!$1:$1048576,27,FALSE),) -> 0 | W10: =IFERROR(VLOOKUP($A10,Data!$1:$1048576,28,FALSE),) -> 0 | X10: =IFERROR(VLOOKUP($A10,Data!$1:$1048576,29,FALSE),) -> 0 | Y10: =IFERROR(VLOOKUP($A10,Data!$1:$1048576,30,FALSE),) -> 0 | Z10: =IFERROR(VLOOKUP($A10,Data!$1:$1048576,31,FALSE),) -> 0 | AA10: =IFERROR(VLOOKUP($A10,Data!$1:$1048576,32,FALSE),) -> 0 | AB10: =IFERROR(VLOOKUP($A10,Data!$1:$1048576,33,FALSE),) -> 0
A11: =Data!A103 -> 0 | B11: =IFERROR(VLOOKUP($A11,Data!$1:$1048576,34,FALSE),) -> 0 | C11: =IFERROR(VLOOKUP($A11,Data!$1:$1048576,2,FALSE),) -> 0 | D11: =IFERROR(VLOOKUP($A11,Data!$1:$1048576,3,FALSE),) -> 0 | E11: =IFERROR(VLOOKUP($A11,Data!$1:$1048576,4,FALSE),) -> 0 | F11: =IFERROR(VLOOKUP($A11,Data!$1:$1048576,6,FALSE),) -> 0 | G11: =IFERROR(VLOOKUP($A11,Data!$1:$1048576,7,FALSE),) -> 0 | H11: =IFERROR(VLOOKUP($A11,Data!$1:$1048576,13,FALSE),) -> 0 | I11: =IFERROR(VLOOKUP($A11,Data!$1:$1048576,14,FALSE),) -> 0 | J11: =IFERROR(VLOOKUP($A11,Data!$1:$1048576,15,FALSE),) -> 0 | K11: =IFERROR(VLOOKUP($A11,Data!$1:$1048576,16,FALSE),) -> 0 | L11: =IFERROR(VLOOKUP($A11,Data!$1:$1048576,17,FALSE),) -> 0 | M11: =IFERROR(VLOOKUP($A11,Data!$1:$1048576,18,FALSE),) -> 0 | N11: =IFERROR(VLOOKUP($A11,Data!$1:$1048576,19,FALSE),) -> 0 | O11: =IFERROR(VLOOKUP($A11,Data!$1:$1048576,20,FALSE),) -> 0 | P11: =IFERROR(VLOOKUP($A11,Data!$1:$1048576,21,FALSE),) -> 0 | Q11: =IFERROR(VLOOKUP($A11,Data!$1:$1048576,22,FALSE),) -> 0 | R11: =IFERROR(VLOOKUP($A11,Data!$1:$1048576,23,FALSE),) -> 0 | S11: =IFERROR(VLOOKUP($A11,Data!$1:$1048576,24,FALSE),) -> 0 | T11: =IFERROR(VLOOKUP($A11,Data!$1:$1048576,25,FALSE),) -> 0 | U11: =IFERROR(VLOOKUP($A11,Data!$1:$1048576,26,FALSE),) -> 0 | V11: =IFERROR(VLOOKUP($A11,Data!$1:$1048576,27,FALSE),) -> 0 | W11: =IFERROR(VLOOKUP($A11,Data!$1:$1048576,28,FALSE),) -> 0 | X11: =IFERROR(VLOOKUP($A11,Data!$1:$1048576,29,FALSE),) -> 0 | Y11: =IFERROR(VLOOKUP($A11,Data!$1:$1048576,30,FALSE),) -> 0 | Z11: =IFERROR(VLOOKUP($A11,Data!$1:$1048576,31,FALSE),) -> 0 | AA11: =IFERROR(VLOOKUP($A11,Data!$1:$1048576,32,FALSE),) -> 0 | AB11: =IFERROR(VLOOKUP($A11,Data!$1:$1048576,33,FALSE),) -> 0
A12: =Data!A104 -> 0 | B12: =IFERROR(VLOOKUP($A12,Data!$1:$1048576,34,FALSE),) -> 0 | C12: =IFERROR(VLOOKUP($A12,Data!$1:$1048576,2,FALSE),) -> 0 | D12: =IFERROR(VLOOKUP($A12,Data!$1:$1048576,3,FALSE),) -> 0 | E12: =IFERROR(VLOOKUP($A12,Data!$1:$1048576,4,FALSE),) -> 0 | F12: =IFERROR(VLOOKUP($A12,Data!$1:$1048576,6,FALSE),) -> 0 | G12: =IFERROR(VLOOKUP($A12,Data!$1:$1048576,7,FALSE),) -> 0 | H12: =IFERROR(VLOOKUP($A12,Data!$1:$1048576,13,FALSE),) -> 0 | I12: =IFERROR(VLOOKUP($A12,Data!$1:$1048576,14,FALSE),) -> 0 | J12: =IFERROR(VLOOKUP($A12,Data!$1:$1048576,15,FALSE),) -> 0 | K12: =IFERROR(VLOOKUP($A12,Data!$1:$1048576,16,FALSE),) -> 0 | L12: =IFERROR(VLOOKUP($A12,Data!$1:$1048576,17,FALSE),) -> 0 | M12: =IFERROR(VLOOKUP($A12,Data!$1:$1048576,18,FALSE),) -> 0 | N12: =IFERROR(VLOOKUP($A12,Data!$1:$1048576,19,FALSE),) -> 0 | O12: =IFERROR(VLOOKUP($A12,Data!$1:$1048576,20,FALSE),) -> 0 | P12: =IFERROR(VLOOKUP($A12,Data!$1:$1048576,21,FALSE),) -> 0 | Q12: =IFERROR(VLOOKUP($A12,Data!$1:$1048576,22,FALSE),) -> 0 | R12: =IFERROR(VLOOKUP($A12,Data!$1:$1048576,23,FALSE),) -> 0 | S12: =IFERROR(VLOOKUP($A12,Data!$1:$1048576,24,FALSE),) -> 0 | T12: =IFERROR(VLOOKUP($A12,Data!$1:$1048576,25,FALSE),) -> 0 | U12: =IFERROR(VLOOKUP($A12,Data!$1:$1048576,26,FALSE),) -> 0 | V12: =IFERROR(VLOOKUP($A12,Data!$1:$1048576,27,FALSE),) -> 0 | W12: =IFERROR(VLOOKUP($A12,Data!$1:$1048576,28,FALSE),) -> 0 | X12: =IFERROR(VLOOKUP($A12,Data!$1:$1048576,29,FALSE),) -> 0 | Y12: =IFERROR(VLOOKUP($A12,Data!$1:$1048576,30,FALSE),) -> 0 | Z12: =IFERROR(VLOOKUP($A12,Data!$1:$1048576,31,FALSE),) -> 0 | AA12: =IFERROR(VLOOKUP($A12,Data!$1:$1048576,32,FALSE),) -> 0 | AB12: =IFERROR(VLOOKUP($A12,Data!$1:$1048576,33,FALSE),) -> 0
A13: =Data!A105 -> 0 | B13: =IFERROR(VLOOKUP($A13,Data!$1:$1048576,34,FALSE),) -> 0 | C13: =IFERROR(VLOOKUP($A13,Data!$1:$1048576,2,FALSE),) -> 0 | D13: =IFERROR(VLOOKUP($A13,Data!$1:$1048576,3,FALSE),) -> 0 | E13: =IFERROR(VLOOKUP($A13,Data!$1:$1048576,4,FALSE),) -> 0 | F13: =IFERROR(VLOOKUP($A13,Data!$1:$1048576,6,FALSE),) -> 0 | G13: =IFERROR(VLOOKUP($A13,Data!$1:$1048576,7,FALSE),) -> 0 | H13: =IFERROR(VLOOKUP($A13,Data!$1:$1048576,13,FALSE),) -> 0 | I13: =IFERROR(VLOOKUP($A13,Data!$1:$1048576,14,FALSE),) -> 0 | J13: =IFERROR(VLOOKUP($A13,Data!$1:$1048576,15,FALSE),) -> 0 | K13: =IFERROR(VLOOKUP($A13,Data!$1:$1048576,16,FALSE),) -> 0 | L13: =IFERROR(VLOOKUP($A13,Data!$1:$1048576,17,FALSE),) -> 0 | M13: =IFERROR(VLOOKUP($A13,Data!$1:$1048576,18,FALSE),) -> 0 | N13: =IFERROR(VLOOKUP($A13,Data!$1:$1048576,19,FALSE),) -> 0 | O13: =IFERROR(VLOOKUP($A13,Data!$1:$1048576,20,FALSE),) -> 0 | P13: =IFERROR(VLOOKUP($A13,Data!$1:$1048576,21,FALSE),) -> 0 | Q13: =IFERROR(VLOOKUP($A13,Data!$1:$1048576,22,FALSE),) -> 0 | R13: =IFERROR(VLOOKUP($A13,Data!$1:$1048576,23,FALSE),) -> 0 | S13: =IFERROR(VLOOKUP($A13,Data!$1:$1048576,24,FALSE),) -> 0 | T13: =IFERROR(VLOOKUP($A13,Data!$1:$1048576,25,FALSE),) -> 0 | U13: =IFERROR(VLOOKUP($A13,Data!$1:$1048576,26,FALSE),) -> 0 | V13: =IFERROR(VLOOKUP($A13,Data!$1:$1048576,27,FALSE),) -> 0 | W13: =IFERROR(VLOOKUP($A13,Data!$1:$1048576,28,FALSE),) -> 0 | X13: =IFERROR(VLOOKUP($A13,Data!$1:$1048576,29,FALSE),) -> 0 | Y13: =IFERROR(VLOOKUP($A13,Data!$1:$1048576,30,FALSE),) -> 0 | Z13: =IFERROR(VLOOKUP($A13,Data!$1:$1048576,31,FALSE),) -> 0 | AA13: =IFERROR(VLOOKUP($A13,Data!$1:$1048576,32,FALSE),) -> 0 | AB13: =IFERROR(VLOOKUP($A13,Data!$1:$1048576,33,FALSE),) -> 0

Sheet Group 32
A1: =E4 -> Kurt
A2: Field | B2: YTD | C2: Farm | D2: Group | E2: Manager | F2: Crop | G2: Variety | H2: =Dates!F2 -> 45453 | I2: =Dates!G2 -> 45460 | J2: =Dates!H2 -> 45467 | K2: =Dates!I2 -> 45474 | L2: =Dates!J2 -> 45481 | M2: =Dates!K2 -> 45488 | N2: =Dates!L2 -> 45495 | O2: =Dates!M2 -> 45502 | ... AB2: =Dates!Z2 -> 45593
A3: Rain | B3: =+SUM(H3:AB3) -> 0.23 | H3: ='Rain Totals'!H2 -> 0 | I3: ='Rain Totals'!I2 -> 0.03 | J3: ='Rain Totals'!J2 -> 0 | K3: ='Rain Totals'!K2 -> 0 | L3: ='Rain Totals'!L2 -> 0.2 | M3: ='Rain Totals'!M2 -> 0 | N3: ='Rain Totals'!N2 -> 0 | O3: ='Rain Totals'!O2 -> 0 | ... AB3: ='Rain Totals'!AB2 -> 0
A4: =Data!A325 -> .ET 32 | B4: =IFERROR(VLOOKUP($A4,Data!$1:$1048576,34,FALSE),) -> 21.75 | C4: =IFERROR(VLOOKUP($A4,Data!$1:$1048576,2,FALSE),) -> Imperial | D4: =IFERROR(VLOOKUP($A4,Data!$1:$1048576,3,FALSE),) -> 32 | E4: =IFERROR(VLOOKUP($A4,Data!$1:$1048576,4,FALSE),) -> Kurt | F4: =IFERROR(VLOOKUP($A4,Data!$1:$1048576,6,FALSE),) -> Spring Grain | G4: =IFERROR(VLOOKUP($A4,Data!$1:$1048576,7,FALSE),) -> Lott Rent | H4: =IFERROR(VLOOKUP($A4,Data!$1:$1048576,13,FALSE),) -> 2.24 | I4: =IFERROR(VLOOKUP($A4,Data!$1:$1048576,14,FALSE),) -> 2.03 | J4: =IFERROR(VLOOKUP($A4,Data!$1:$1048576,15,FALSE),) -> 1.99 | K4: =IFERROR(VLOOKUP($A4,Data!$1:$1048576,16,FALSE),) -> 1.94 | L4: =IFERROR(VLOOKUP($A4,Data!$1:$1048576,17,FALSE),) -> 1.68 | M4: =IFERROR(VLOOKUP($A4,Data!$1:$1048576,18,FALSE),) -> 1.69 | N4: =IFERROR(VLOOKUP($A4,Data!$1:$1048576,19,FALSE),) -> 1.77 | O4: =IFERROR(VLOOKUP($A4,Data!$1:$1048576,20,FALSE),) -> 1.82 | P4: =IFERROR(VLOOKUP($A4,Data!$1:$1048576,21,FALSE),) -> 1.61 | Q4: =IFERROR(VLOOKUP($A4,Data!$1:$1048576,22,FALSE),) -> 1.22 | R4: =IFERROR(VLOOKUP($A4,Data!$1:$1048576,23,FALSE),) -> 0.13 | S4: =IFERROR(VLOOKUP($A4,Data!$1:$1048576,24,FALSE),) -> 0 | T4: =IFERROR(VLOOKUP($A4,Data!$1:$1048576,25,FALSE),) -> 0 | U4: =IFERROR(VLOOKUP($A4,Data!$1:$1048576,26,FALSE),) -> 0 | V4: =IFERROR(VLOOKUP($A4,Data!$1:$1048576,27,FALSE),) -> 0 | W4: =IFERROR(VLOOKUP($A4,Data!$1:$1048576,28,FALSE),) -> 0 | X4: =IFERROR(VLOOKUP($A4,Data!$1:$1048576,29,FALSE),) -> 0 | Y4: =IFERROR(VLOOKUP($A4,Data!$1:$1048576,30,FALSE),) -> 0 | Z4: =IFERROR(VLOOKUP($A4,Data!$1:$1048576,31,FALSE),) -> 0 | AA4: =IFERROR(VLOOKUP($A4,Data!$1:$1048576,32,FALSE),) -> 0 | AB4: =IFERROR(VLOOKUP($A4,Data!$1:$1048576,33,FALSE),) -> 0
A5: =Data!A326 -> I-26 | B5: =IFERROR(VLOOKUP($A5,Data!$1:$1048576,34,FALSE),) -> 0 | C5: =IFERROR(VLOOKUP($A5,Data!$1:$1048576,2,FALSE),) -> Imperial | D5: =IFERROR(VLOOKUP($A5,Data!$1:$1048576,3,FALSE),) -> 32 | E5: =IFERROR(VLOOKUP($A5,Data!$1:$1048576,4,FALSE),) -> Kurt | F5: =IFERROR(VLOOKUP($A5,Data!$1:$1048576,6,FALSE),) -> Spring Grain | G5: =IFERROR(VLOOKUP($A5,Data!$1:$1048576,7,FALSE),) -> Lott Rent | H5: =IFERROR(VLOOKUP($A5,Data!$1:$1048576,13,FALSE),) | I5: =IFERROR(VLOOKUP($A5,Data!$1:$1048576,14,FALSE),) -> 0 | J5: =IFERROR(VLOOKUP($A5,Data!$1:$1048576,15,FALSE),) -> 0 | K5: =IFERROR(VLOOKUP($A5,Data!$1:$1048576,16,FALSE),) -> 0 | L5: =IFERROR(VLOOKUP($A5,Data!$1:$1048576,17,FALSE),) -> 0 | M5: =IFERROR(VLOOKUP($A5,Data!$1:$1048576,18,FALSE),) -> 0 | N5: =IFERROR(VLOOKUP($A5,Data!$1:$1048576,19,FALSE),) -> 0 | O5: =IFERROR(VLOOKUP($A5,Data!$1:$1048576,20,FALSE),) -> 0 | P5: =IFERROR(VLOOKUP($A5,Data!$1:$1048576,21,FALSE),) -> 0 | Q5: =IFERROR(VLOOKUP($A5,Data!$1:$1048576,22,FALSE),) -> 0 | R5: =IFERROR(VLOOKUP($A5,Data!$1:$1048576,23,FALSE),) -> 0 | S5: =IFERROR(VLOOKUP($A5,Data!$1:$1048576,24,FALSE),) -> 0 | T5: =IFERROR(VLOOKUP($A5,Data!$1:$1048576,25,FALSE),) -> 0 | U5: =IFERROR(VLOOKUP($A5,Data!$1:$1048576,26,FALSE),) -> 0 | V5: =IFERROR(VLOOKUP($A5,Data!$1:$1048576,27,FALSE),) -> 0 | W5: =IFERROR(VLOOKUP($A5,Data!$1:$1048576,28,FALSE),) -> 0 | X5: =IFERROR(VLOOKUP($A5,Data!$1:$1048576,29,FALSE),) -> 0 | Y5: =IFERROR(VLOOKUP($A5,Data!$1:$1048576,30,FALSE),) -> 0 | Z5: =IFERROR(VLOOKUP($A5,Data!$1:$1048576,31,FALSE),) -> 0 | AA5: =IFERROR(VLOOKUP($A5,Data!$1:$1048576,32,FALSE),) -> 0 | AB5: =IFERROR(VLOOKUP($A5,Data!$1:$1048576,33,FALSE),) -> 0
A6: =Data!A327 -> I-27 | B6: =IFERROR(VLOOKUP($A6,Data!$1:$1048576,34,FALSE),) -> 19.6 | C6: =IFERROR(VLOOKUP($A6,Data!$1:$1048576,2,FALSE),) -> Imperial | D6: =IFERROR(VLOOKUP($A6,Data!$1:$1048576,3,FALSE),) -> 32 | E6: =IFERROR(VLOOKUP($A6,Data!$1:$1048576,4,FALSE),) -> Kurt | F6: =IFERROR(VLOOKUP($A6,Data!$1:$1048576,6,FALSE),) -> Spring Grain | G6: =IFERROR(VLOOKUP($A6,Data!$1:$1048576,7,FALSE),) -> Lott Rent | H6: =IFERROR(VLOOKUP($A6,Data!$1:$1048576,13,FALSE),) | I6: =IFERROR(VLOOKUP($A6,Data!$1:$1048576,14,FALSE),) -> 1.47 | J6: =IFERROR(VLOOKUP($A6,Data!$1:$1048576,15,FALSE),) -> 2.34 | K6: =IFERROR(VLOOKUP($A6,Data!$1:$1048576,16,FALSE),) -> 5.17 | L6: =IFERROR(VLOOKUP($A6,Data!$1:$1048576,17,FALSE),) -> 1.98 | M6: =IFERROR(VLOOKUP($A6,Data!$1:$1048576,18,FALSE),) -> 2.3 | N6: =IFERROR(VLOOKUP($A6,Data!$1:$1048576,19,FALSE),) -> 2.14 | O6: =IFERROR(VLOOKUP($A6,Data!$1:$1048576,20,FALSE),) -> 0.17 | P6: =IFERROR(VLOOKUP($A6,Data!$1:$1048576,21,FALSE),) -> 0 | Q6: =IFERROR(VLOOKUP($A6,Data!$1:$1048576,22,FALSE),) -> 0 | R6: =IFERROR(VLOOKUP($A6,Data!$1:$1048576,23,FALSE),) -> 0 | S6: =IFERROR(VLOOKUP($A6,Data!$1:$1048576,24,FALSE),) -> 0 | T6: =IFERROR(VLOOKUP($A6,Data!$1:$1048576,25,FALSE),) -> 0 | U6: =IFERROR(VLOOKUP($A6,Data!$1:$1048576,26,FALSE),) -> 0.01 | V6: =IFERROR(VLOOKUP($A6,Data!$1:$1048576,27,FALSE),) -> 0 | W6: =IFERROR(VLOOKUP($A6,Data!$1:$1048576,28,FALSE),) -> 0 | X6: =IFERROR(VLOOKUP($A6,Data!$1:$1048576,29,FALSE),) -> 0 | Y6: =IFERROR(VLOOKUP($A6,Data!$1:$1048576,30,FALSE),) -> 0 | Z6: =IFERROR(VLOOKUP($A6,Data!$1:$1048576,31,FALSE),) -> 0 | AA6: =IFERROR(VLOOKUP($A6,Data!$1:$1048576,32,FALSE),) -> 0 | AB6: =IFERROR(VLOOKUP($A6,Data!$1:$1048576,33,FALSE),) -> 0
